Workbook
Name ___Div01: #REF!
Name ___Div02: #REF!
Name ___Div03: #REF!
Name ___Div04: #REF!
Name ___Div05: #REF!
Name ___Div06: #REF!
Name ___Div07: #REF!
Name ___Div08: #REF!
Name ___Div09: #REF!
Name ___Div10: #REF!
Name __Div01: #REF!
Name __Div02: #REF!
Name __Div03: #REF!
Name __Div04: #REF!
Name __Div05: #REF!
Name __Div06: #REF!
Name __Div07: #REF!
Name __Div08: #REF!
Name __Div09: #REF!
Name __Div10: #REF!
Name _10Excel_BuiltIn_Print_Area_19_1: "$#REF!.$B$1:$F$239"
Name _11Excel_BuiltIn_Print_Area_19_1_1: "$#REF!.$B$1:$F$239"
Name _12Excel_BuiltIn_Print_Area_20_1: "$#REF!.$B$1:$F$59"
Name _13Excel_BuiltIn_Print_Area_20_1_1: "$#REF!.$B$1:$F$59"
Name _14Excel_BuiltIn_Print_Area_21_1: "$#REF!.$B$1:$F$79"
Name _15Excel_BuiltIn_Print_Area_21_1_1: "$#REF!.$B$1:$F$79"
Name _16Excel_BuiltIn_Print_Area_22_1: "$#REF!.$B$1:$F$21"
Name _17Excel_BuiltIn_Print_Area_22_1_1: "$#REF!.$B$1:$F$21"
Name _18Excel_BuiltIn_Print_Area_24_1: "$#REF!.$B$1:$F$14"
Name _19Excel_BuiltIn_Print_Area_24_1_1: "$#REF!.$B$1:$F$14"
Name _1Excel_BuiltIn_Print_Area_1_1_1_1_1: "$#REF!.$#REF!$#REF!"
Name _20Excel_BuiltIn_Print_Area_25_1: "$#REF!.$B$1:$F$12"
Name _21Excel_BuiltIn_Print_Area_25_1_1: "$#REF!.$B$1:$F$12"
Name _22Excel_BuiltIn_Print_Area_3_1_1_1_1: "$#REF!.$A$1:$AH$218"
Name _23Excel_BuiltIn_Print_Area_3_1_1_1_1_1: "$#REF!.$A$1:$AG$63"
Name _24Excel_BuiltIn_Print_Area_3_1_1_1_1_1_1_1: "$#REF!.$A$1:$AG$52"
Name _25Excel_BuiltIn_Print_Area_3_1_1_1_1_1_1_1_1: "$#REF!.$A$1:$AG$52"
Name _26Excel_BuiltIn_Print_Area_5_1_1_1_1: "$#REF!.$B$1:$F$79"
Name _27Excel_BuiltIn_Print_Area_5_1_1_1_1_1: "$#REF!.$B$1:$F$39"
Name _28Excel_BuiltIn_Print_Area_6_1_1_1_1: "$#REF!.$B$1:$F$48"
Name _29Excel_BuiltIn_Print_Area_6_1_1_1_1_1: "$#REF!.$B$1:$F$48"
Name _2Excel_BuiltIn_Print_Area_1_1_1_1_1_1: "$#REF!.$B$1:$F$62"
Name _30Excel_BuiltIn_Print_Titles_13_1_1_1: "$#REF!.$B$1:$G$65509"
Name _31Excel_BuiltIn_Print_Titles_13_1_1_1_1: "$#REF!.$B$1:$G$65509"
Name _32Excel_BuiltIn_Print_Titles_15_1_1: "$#REF!.$B$1:$G$65509"
Name _33Excel_BuiltIn_Print_Titles_15_1_1_1: "$#REF!.$B$1:$G$65509"
Name _34Excel_BuiltIn_Print_Titles_16_1: #REF!
Name _3Excel_BuiltIn_Print_Area_1_1_1_1_1_1_1: "$#REF!.$B$1:$F$50"
Name _4Excel_BuiltIn_Print_Area_1_1_1_1_1_1_1_1: "$#REF!.$B$1:$F$50"
Name _5Excel_BuiltIn_Print_Area_1_1_1_1_1_1_1_1_1: "$#REF!.$B$1:$F$50"
Name _6Excel_BuiltIn_Print_Area_17_1: "$#REF!.$B$1:$F$51"
Name _7Excel_BuiltIn_Print_Area_17_1_1: "$#REF!.$B$1:$F$51"
Name _8Excel_BuiltIn_Print_Area_18_1: "$#REF!.$B$1:$F$38"
Name _9Excel_BuiltIn_Print_Area_18_1_1: "$#REF!.$B$1:$F$38"
Name _a: NA()
Name _a_1: "$#REF!.$#REF!$#REF!"
Name _a_1_1: "$#REF!.$#REF!$#REF!"
Name _a_14: "$#REF!.$#REF!$#REF!"
Name _b: "$#REF!.$#REF!$#REF!"
Name _b_1: "$#REF!.$#REF!$#REF!"

Sheet LS (Sensus) 
A2: Laporan Blok Yang Sudah Dikerjakan dan Blok InProgress
A3: Kebun | B3: Est | C3: Afd | D3: Blok | E3: Luas (Ha) | F3: Jenis Tanah | G3: Total Pokok Produktif | H3: Tanggal Sensus | I3: Pokok Sensus | J3: Pokok Sensus (%) | K3: Pokok Terserang (Baru) | L3: % | M3: Rekomendasi
A6: LS I | B6: I | C6: I | D6: B05 | E6: 29.32 | F6: GAMBUT | G6: 3615 | H6: {=INDEX([22]Monitoring!$H$6:$H$582,MATCH(1,([22]Monitoring!$D$6:$D$582=$D6)*([22]Monitoring!$D$6:$D$582=$D6),0))} -> 46148 | I6: {=INDEX([22]Monitoring!$I$6:$I$582,MATCH(1,([22]Monitoring!$D$6:$D$582=$D6)*([22]Monitoring!$D$6:$D$582=$D6),0))} -> 312 | J6: {=IFERROR(I6/G6*100,0)} -> 8.6307054 | K6: {=INDEX([22]Monitoring!$J$6:$J$582,MATCH(1,([22]Monitoring!$D$6:$D$582=$D6)*([22]Monitoring!$D$6:$D$582=$D6),0))} -> 22 | L6: =IFERROR(K6/I6*100,0) -> 7.0512821 | M6: {=IF(L6>5,"Perlu Pengendalian",IF(AND(L6>=0,I6>0),"Tidak Perlu Pengendalian","Belum Sensus"))} -> Perlu Pengendalian
A7: LS I | B7: I | C7: I | D7: B06 | E7: 22.39 | F7: GAMBUT | G7: 3145 | H7: {=INDEX([22]Monitoring!$H$6:$H$582,MATCH(1,([22]Monitoring!$D$6:$D$582=$D7)*([22]Monitoring!$D$6:$D$582=$D7),0))} -> 46148 | I7: {=INDEX([22]Monitoring!$I$6:$I$582,MATCH(1,([22]Monitoring!$D$6:$D$582=$D7)*([22]Monitoring!$D$6:$D$582=$D7),0))} -> 321 | J7: {=IFERROR(I7/G7*100,0)} -> 10.206677 | K7: {=INDEX([22]Monitoring!$J$6:$J$582,MATCH(1,([22]Monitoring!$D$6:$D$582=$D7)*([22]Monitoring!$D$6:$D$582=$D7),0))} -> 24 | L7: =IFERROR(K7/I7*100,0) -> 7.4766355 | M7: {=IF(L7>5,"Perlu Pengendalian",IF(AND(L7>=0,I7>0),"Tidak Perlu Pengendalian","Belum Sensus"))} -> Perlu Pengendalian
A8: LS I | B8: I | C8: I | D8: B07 | E8: 25.74 | F8: GAMBUT | G8: 3551 | H8: {=INDEX([22]Monitoring!$H$6:$H$582,MATCH(1,([22]Monitoring!$D$6:$D$582=$D8)*([22]Monitoring!$D$6:$D$582=$D8),0))} -> 46148 | I8: {=INDEX([22]Monitoring!$I$6:$I$582,MATCH(1,([22]Monitoring!$D$6:$D$582=$D8)*([22]Monitoring!$D$6:$D$582=$D8),0))} -> 361 | J8: {=IFERROR(I8/G8*100,0)} -> 10.16615 | K8: {=INDEX([22]Monitoring!$J$6:$J$582,MATCH(1,([22]Monitoring!$D$6:$D$582=$D8)*([22]Monitoring!$D$6:$D$582=$D8),0))} -> 20 | L8: =IFERROR(K8/I8*100,0) -> 5.5401662 | M8: {=IF(L8>5,"Perlu Pengendalian",IF(AND(L8>=0,I8>0),"Tidak Perlu Pengendalian","Belum Sensus"))} -> Perlu Pengendalian
A9: LS I | B9: I | C9: I | D9: B08 | E9: 29.3 | F9: GAMBUT | G9: 4705 | H9: {=INDEX([22]Monitoring!$H$6:$H$582,MATCH(1,([22]Monitoring!$D$6:$D$582=$D9)*([22]Monitoring!$D$6:$D$582=$D9),0))} -> 46148 | I9: {=INDEX([22]Monitoring!$I$6:$I$582,MATCH(1,([22]Monitoring!$D$6:$D$582=$D9)*([22]Monitoring!$D$6:$D$582=$D9),0))} -> 397 | J9: {=IFERROR(I9/G9*100,0)} -> 8.4378321 | K9: {=INDEX([22]Monitoring!$J$6:$J$582,MATCH(1,([22]Monitoring!$D$6:$D$582=$D9)*([22]Monitoring!$D$6:$D$582=$D9),0))} -> 30 | L9: =IFERROR(K9/I9*100,0) -> 7.5566751 | M9: {=IF(L9>5,"Perlu Pengendalian",IF(AND(L9>=0,I9>0),"Tidak Perlu Pengendalian","Belum Sensus"))} -> Perlu Pengendalian
A10: LS I | B10: I | C10: I | D10: B09 | E10: 31.12 | F10: GAMBUT | G10: 4836 | H10: {=INDEX([22]Monitoring!$H$6:$H$582,MATCH(1,([22]Monitoring!$D$6:$D$582=$D10)*([22]Monitoring!$D$6:$D$582=$D10),0))} -> 46148 | I10: {=INDEX([22]Monitoring!$I$6:$I$582,MATCH(1,([22]Monitoring!$D$6:$D$582=$D10)*([22]Monitoring!$D$6:$D$582=$D10),0))} -> 380 | J10: {=IFERROR(I10/G10*100,0)} -> 7.8577337 | K10: {=INDEX([22]Monitoring!$J$6:$J$582,MATCH(1,([22]Monitoring!$D$6:$D$582=$D10)*([22]Monitoring!$D$6:$D$582=$D10),0))} -> 30 | L10: =IFERROR(K10/I10*100,0) -> 7.8947368 | M10: {=IF(L10>5,"Perlu Pengendalian",IF(AND(L10>=0,I10>0),"Tidak Perlu Pengendalian","Belum Sensus"))} -> Perlu Pengendalian
A11: LS I | B11: I | C11: I | D11: B10 | E11: 36.85 | F11: GAMBUT | G11: 5351 | H11: {=INDEX([22]Monitoring!$H$6:$H$582,MATCH(1,([22]Monitoring!$D$6:$D$582=$D11)*([22]Monitoring!$D$6:$D$582=$D11),0))} -> 46149 | I11: {=INDEX([22]Monitoring!$I$6:$I$582,MATCH(1,([22]Monitoring!$D$6:$D$582=$D11)*([22]Monitoring!$D$6:$D$582=$D11),0))} -> 391 | J11: {=IFERROR(I11/G11*100,0)} -> 7.3070454 | K11: {=INDEX([22]Monitoring!$J$6:$J$582,MATCH(1,([22]Monitoring!$D$6:$D$582=$D11)*([22]Monitoring!$D$6:$D$582=$D11),0))} -> 71 | L11: =IFERROR(K11/I11*100,0) -> 18.158568 | M11: {=IF(L11>5,"Perlu Pengendalian",IF(AND(L11>=0,I11>0),"Tidak Perlu Pengendalian","Belum Sensus"))} -> Perlu Pengendalian
A12: LS I | B12: I | C12: I | D12: B11 | E12: 31.93 | F12: GAMBUT | G12: 4122 | H12: {=INDEX([22]Monitoring!$H$6:$H$582,MATCH(1,([22]Monitoring!$D$6:$D$582=$D12)*([22]Monitoring!$D$6:$D$582=$D12),0))} -> 46149 | I12: {=INDEX([22]Monitoring!$I$6:$I$582,MATCH(1,([22]Monitoring!$D$6:$D$582=$D12)*([22]Monitoring!$D$6:$D$582=$D12),0))} -> 324 | J12: {=IFERROR(I12/G12*100,0)} -> 7.860262 | K12: {=INDEX([22]Monitoring!$J$6:$J$582,MATCH(1,([22]Monitoring!$D$6:$D$582=$D12)*([22]Monitoring!$D$6:$D$582=$D12),0))} -> 71 | L12: =IFERROR(K12/I12*100,0) -> 21.91358 | M12: {=IF(L12>5,"Perlu Pengendalian",IF(AND(L12>=0,I12>0),"Tidak Perlu Pengendalian","Belum Sensus"))} -> Perlu Pengendalian
A13: LS I | B13: I | C13: I | D13: B12 | E13: 37.13 | F13: GAMBUT | G13: 4726 | H13: {=INDEX([22]Monitoring!$H$6:$H$582,MATCH(1,([22]Monitoring!$D$6:$D$582=$D13)*([22]Monitoring!$D$6:$D$582=$D13),0))} -> 46149 | I13: {=INDEX([22]Monitoring!$I$6:$I$582,MATCH(1,([22]Monitoring!$D$6:$D$582=$D13)*([22]Monitoring!$D$6:$D$582=$D13),0))} -> 320 | J13: {=IFERROR(I13/G13*100,0)} -> 6.7710537 | K13: {=INDEX([22]Monitoring!$J$6:$J$582,MATCH(1,([22]Monitoring!$D$6:$D$582=$D13)*([22]Monitoring!$D$6:$D$582=$D13),0))} -> 51 | L13: =IFERROR(K13/I13*100,0) -> 15.9375 | M13: {=IF(L13>5,"Perlu Pengendalian",IF(AND(L13>=0,I13>0),"Tidak Perlu Pengendalian","Belum Sensus"))} -> Perlu Pengendalian
A14: LS I | B14: I | C14: I | D14: B13 | E14: 33.49 | F14: GAMBUT | G14: 3913 | H14: {=INDEX([22]Monitoring!$H$6:$H$582,MATCH(1,([22]Monitoring!$D$6:$D$582=$D14)*([22]Monitoring!$D$6:$D$582=$D14),0))} -> 46149 | I14: {=INDEX([22]Monitoring!$I$6:$I$582,MATCH(1,([22]Monitoring!$D$6:$D$582=$D14)*([22]Monitoring!$D$6:$D$582=$D14),0))} -> 388 | J14: {=IFERROR(I14/G14*100,0)} -> 9.9156657 | K14: {=INDEX([22]Monitoring!$J$6:$J$582,MATCH(1,([22]Monitoring!$D$6:$D$582=$D14)*([22]Monitoring!$D$6:$D$582=$D14),0))} -> 44 | L14: =IFERROR(K14/I14*100,0) -> 11.340206 | M14: {=IF(L14>5,"Perlu Pengendalian",IF(AND(L14>=0,I14>0),"Tidak Perlu Pengendalian","Belum Sensus"))} -> Perlu Pengendalian
A15: LS I | B15: I | C15: I | D15: B14 | E15: 29.45 | F15: GAMBUT | G15: 3806 | H15: {=INDEX([22]Monitoring!$H$6:$H$582,MATCH(1,([22]Monitoring!$D$6:$D$582=$D15)*([22]Monitoring!$D$6:$D$582=$D15),0))} -> 46150 | I15: {=INDEX([22]Monitoring!$I$6:$I$582,MATCH(1,([22]Monitoring!$D$6:$D$582=$D15)*([22]Monitoring!$D$6:$D$582=$D15),0))} -> 322 | J15: {=IFERROR(I15/G15*100,0)} -> 8.4603258 | K15: {=INDEX([22]Monitoring!$J$6:$J$582,MATCH(1,([22]Monitoring!$D$6:$D$582=$D15)*([22]Monitoring!$D$6:$D$582=$D15),0))} -> 60 | L15: =IFERROR(K15/I15*100,0) -> 18.63354 | M15: {=IF(L15>5,"Perlu Pengendalian",IF(AND(L15>=0,I15>0),"Tidak Perlu Pengendalian","Belum Sensus"))} -> Perlu Pengendalian
A16: LS I | B16: I | C16: I | D16: B15 | E16: 24.51 | F16: GAMBUT | G16: 3672 | H16: {=INDEX([22]Monitoring!$H$6:$H$582,MATCH(1,([22]Monitoring!$D$6:$D$582=$D16)*([22]Monitoring!$D$6:$D$582=$D16),0))} -> 46150 | I16: {=INDEX([22]Monitoring!$I$6:$I$582,MATCH(1,([22]Monitoring!$D$6:$D$582=$D16)*([22]Monitoring!$D$6:$D$582=$D16),0))} -> 386 | J16: {=IFERROR(I16/G16*100,0)} -> 10.511983 | K16: {=INDEX([22]Monitoring!$J$6:$J$582,MATCH(1,([22]Monitoring!$D$6:$D$582=$D16)*([22]Monitoring!$D$6:$D$582=$D16),0))} -> 37 | L16: =IFERROR(K16/I16*100,0) -> 9.5854922 | M16: {=IF(L16>5,"Perlu Pengendalian",IF(AND(L16>=0,I16>0),"Tidak Perlu Pengendalian","Belum Sensus"))} -> Perlu Pengendalian
A17: LS I | B17: I | C17: I | D17: B16 | E17: 24.21 | F17: GAMBUT | G17: 3591 | H17: {=INDEX([22]Monitoring!$H$6:$H$582,MATCH(1,([22]Monitoring!$D$6:$D$582=$D17)*([22]Monitoring!$D$6:$D$582=$D17),0))} -> 46150 | I17: {=INDEX([22]Monitoring!$I$6:$I$582,MATCH(1,([22]Monitoring!$D$6:$D$582=$D17)*([22]Monitoring!$D$6:$D$582=$D17),0))} -> 345 | J17: {=IFERROR(I17/G17*100,0)} -> 9.6073517 | K17: {=INDEX([22]Monitoring!$J$6:$J$582,MATCH(1,([22]Monitoring!$D$6:$D$582=$D17)*([22]Monitoring!$D$6:$D$582=$D17),0))} -> 59 | L17: =IFERROR(K17/I17*100,0) -> 17.101449 | M17: {=IF(L17>5,"Perlu Pengendalian",IF(AND(L17>=0,I17>0),"Tidak Perlu Pengendalian","Belum Sensus"))} -> Perlu Pengendalian
... A582: LS II | B582: IV | C582: XVIII | D582: S64 | E582: 26.27 | F582: PASIR | G582: 3549 | H582: {=INDEX([22]Monitoring!$H$6:$H$582,MATCH(1,([22]Monitoring!$D$6:$D$582=$D582)*([22]Monitoring!$D$6:$D$582=$D582),0))} -> 46153 | I582: {=INDEX([22]Monitoring!$I$6:$I$582,MATCH(1,([22]Monitoring!$D$6:$D$582=$D582)*([22]Monitoring!$D$6:$D$582=$D582),0))} -> 403 | J582: {=IFERROR(I582/G582*100,0)} -> 11.355311 | K582: {=INDEX([22]Monitoring!$J$6:$J$582,MATCH(1,([22]Monitoring!$D$6:$D$582=$D582)*([22]Monitoring!$D$6:$D$582=$D582),0))} -> 13 | L582: =IFERROR(K582/I582*100,0) -> 3.2258065 | M582: {=IF(L582>5,"Perlu Pengendalian",IF(AND(L582>=0,I582>0),"Tidak Perlu Pengendalian","Belum Sensus"))} -> Tidak Perlu Pengendalian
A583: LS I | B583: I | C583: I | D583: {=COUNTIFS($C$6:$C$582,$C583)} -> 31 | E583: =SUMIFS($E$6:$E$582,$C$6:$C$582,$C583) -> 922.58 | G583: =SUMIFS($G$6:$G$582,$C$6:$C$582,$C583) -> 124833 | I583: =SUMIFS($I$6:$I$582,$C$6:$C$582,$C583) -> 11328 | J583: {=IFERROR(I583/G583*100,0)} -> 9.0745236 | K583: =SUMIFS($K$6:$K$582,$C$6:$C$582,$C583) -> 1780 | L583: =IFERROR(K583/I583*100,0) -> 15.713277 | M583: =IF(L583>2,"Perlu Pengendalian",IF(L583>0,"Tidak Perlu Pengendalian","Belum Sensus")) -> Perlu Pengendalian
A584: LS I | B584: I | C584: II | D584: {=COUNTIFS($C$6:$C$582,$C584)} -> 31 | E584: =SUMIFS($E$6:$E$582,$C$6:$C$582,$C584) -> 1001.28 | G584: =SUMIFS($G$6:$G$582,$C$6:$C$582,$C584) -> 138506 | I584: =SUMIFS($I$6:$I$582,$C$6:$C$582,$C584) -> 14005 | J584: {=IFERROR(I584/G584*100,0)} -> 10.111475 | K584: =SUMIFS($K$6:$K$582,$C$6:$C$582,$C584) -> 1604 | L584: =IFERROR(K584/I584*100,0) -> 11.453052 | M584: =IF(L584>2,"Perlu Pengendalian",IF(L584>0,"Tidak Perlu Pengendalian","Belum Sensus")) -> Perlu Pengendalian
A585: LS I | B585: I | C585: III | D585: {=COUNTIFS($C$6:$C$582,$C585)} -> 27 | E585: =SUMIFS($E$6:$E$582,$C$6:$C$582,$C585) -> 940.47 | G585: =SUMIFS($G$6:$G$582,$C$6:$C$582,$C585) -> 121141 | I585: =SUMIFS($I$6:$I$582,$C$6:$C$582,$C585) -> 12530 | J585: {=IFERROR(I585/G585*100,0)} -> 10.343319 | K585: =SUMIFS($K$6:$K$582,$C$6:$C$582,$C585) -> 1299 | L585: =IFERROR(K585/I585*100,0) -> 10.367119 | M585: =IF(L585>2,"Perlu Pengendalian",IF(L585>0,"Tidak Perlu Pengendalian","Belum Sensus")) -> Perlu Pengendalian
A586: LS I | B586: I | C586: IV | D586: {=COUNTIFS($C$6:$C$582,$C586)} -> 35 | E586: =SUMIFS($E$6:$E$582,$C$6:$C$582,$C586) -> 961 | G586: =SUMIFS($G$6:$G$582,$C$6:$C$582,$C586) -> 134476 | I586: =SUMIFS($I$6:$I$582,$C$6:$C$582,$C586) -> 14200 | J586: {=IFERROR(I586/G586*100,0)} -> 10.559505 | K586: =SUMIFS($K$6:$K$582,$C$6:$C$582,$C586) -> 1629 | L586: =IFERROR(K586/I586*100,0) -> 11.471831 | M586: =IF(L586>2,"Perlu Pengendalian",IF(L586>0,"Tidak Perlu Pengendalian","Belum Sensus")) -> Perlu Pengendalian
A587: LS I | B587: I | C587: V | D587: {=COUNTIFS($C$6:$C$582,$C587)} -> 28 | E587: =SUMIFS($E$6:$E$582,$C$6:$C$582,$C587) -> 898.87 | G587: =SUMIFS($G$6:$G$582,$C$6:$C$582,$C587) -> 131840 | I587: =SUMIFS($I$6:$I$582,$C$6:$C$582,$C587) -> 12892 | J587: {=IFERROR(I587/G587*100,0)} -> 9.7785194 | K587: =SUMIFS($K$6:$K$582,$C$6:$C$582,$C587) -> 1647 | L587: =IFERROR(K587/I587*100,0) -> 12.775365 | M587: =IF(L587>2,"Perlu Pengendalian",IF(L587>0,"Tidak Perlu Pengendalian","Belum Sensus")) -> Perlu Pengendalian
A588: LS I | B588: II | C588: VI | D588: {=COUNTIFS($C$6:$C$582,$C588)} -> 42 | E588: =SUMIFS($E$6:$E$582,$C$6:$C$582,$C588) -> 1117.05 | G588: =SUMIFS($G$6:$G$582,$C$6:$C$582,$C588) -> 156536 | I588: =SUMIFS($I$6:$I$582,$C$6:$C$582,$C588) -> 15000 | J588: {=IFERROR(I588/G588*100,0)} -> 9.5824603 | K588: =SUMIFS($K$6:$K$582,$C$6:$C$582,$C588) -> 988 | L588: =IFERROR(K588/I588*100,0) -> 6.5866667 | M588: =IF(L588>2,"Perlu Pengendalian",IF(L588>0,"Tidak Perlu Pengendalian","Belum Sensus")) -> Perlu Pengendalian
A589: LS I | B589: II | C589: VII | D589: {=COUNTIFS($C$6:$C$582,$C589)} -> 35 | E589: =SUMIFS($E$6:$E$582,$C$6:$C$582,$C589) -> 964.15 | G589: =SUMIFS($G$6:$G$582,$C$6:$C$582,$C589) -> 141905 | I589: =SUMIFS($I$6:$I$582,$C$6:$C$582,$C589) -> 13429 | J589: {=IFERROR(I589/G589*100,0)} -> 9.4633734 | K589: =SUMIFS($K$6:$K$582,$C$6:$C$582,$C589) -> 1107 | L589: =IFERROR(K589/I589*100,0) -> 8.2433539 | M589: =IF(L589>2,"Perlu Pengendalian",IF(L589>0,"Tidak Perlu Pengendalian","Belum Sensus")) -> Perlu Pengendalian
A590: LS I | B590: II | C590: VIII | D590: {=COUNTIFS($C$6:$C$582,$C590)} -> 37 | E590: =SUMIFS($E$6:$E$582,$C$6:$C$582,$C590) -> 967.71 | G590: =SUMIFS($G$6:$G$582,$C$6:$C$582,$C590) -> 141747 | I590: =SUMIFS($I$6:$I$582,$C$6:$C$582,$C590) -> 14919 | J590: {=IFERROR(I590/G590*100,0)} -> 10.52509 | K590: =SUMIFS($K$6:$K$582,$C$6:$C$582,$C590) -> 1142 | L590: =IFERROR(K590/I590*100,0) -> 7.6546685 | M590: =IF(L590>2,"Perlu Pengendalian",IF(L590>0,"Tidak Perlu Pengendalian","Belum Sensus")) -> Perlu Pengendalian
A591: LS I | B591: II | C591: IX | D591: {=COUNTIFS($C$6:$C$582,$C591)} -> 31 | E591: =SUMIFS($E$6:$E$582,$C$6:$C$582,$C591) -> 890.99 | G591: =SUMIFS($G$6:$G$582,$C$6:$C$582,$C591) -> 127593 | I591: =SUMIFS($I$6:$I$582,$C$6:$C$582,$C591) -> 11906 | J591: {=IFERROR(I591/G591*100,0)} -> 9.3312329 | K591: =SUMIFS($K$6:$K$582,$C$6:$C$582,$C591) -> 1633 | L591: =IFERROR(K591/I591*100,0) -> 13.715774 | M591: =IF(L591>2,"Perlu Pengendalian",IF(L591>0,"Tidak Perlu Pengendalian","Belum Sensus")) -> Perlu Pengendalian
A592: LS II | B592: III | C592: X | D592: {=COUNTIFS($C$6:$C$582,$C592)} -> 20 | E592: =SUMIFS($E$6:$E$582,$C$6:$C$582,$C592) -> 592.25 | G592: =SUMIFS($G$6:$G$582,$C$6:$C$582,$C592) -> 82098 | I592: =SUMIFS($I$6:$I$582,$C$6:$C$582,$C592) -> 8146 | J592: {=IFERROR(I592/G592*100,0)} -> 9.922288 | K592: =SUMIFS($K$6:$K$582,$C$6:$C$582,$C592) -> 1283 | L592: =IFERROR(K592/I592*100,0) -> 15.750061 | M592: =IF(L592>2,"Perlu Pengendalian",IF(L592>0,"Tidak Perlu Pengendalian","Belum Sensus")) -> Perlu Pengendalian
A593: LS II | B593: III | C593: XI | D593: {=COUNTIFS($C$6:$C$582,$C593)} -> 34 | E593: =SUMIFS($E$6:$E$582,$C$6:$C$582,$C593) -> 969.04 | G593: =SUMIFS($G$6:$G$582,$C$6:$C$582,$C593) -> 134915 | I593: =SUMIFS($I$6:$I$582,$C$6:$C$582,$C593) -> 12816 | J593: {=IFERROR(I593/G593*100,0)} -> 9.4993144 | K593: =SUMIFS($K$6:$K$582,$C$6:$C$582,$C593) -> 1886 | L593: =IFERROR(K593/I593*100,0) -> 14.71598 | M593: =IF(L593>2,"Perlu Pengendalian",IF(L593>0,"Tidak Perlu Pengendalian","Belum Sensus")) -> Perlu Pengendalian
A594: LS II | B594: III | C594: XII | D594: {=COUNTIFS($C$6:$C$582,$C594)} -> 35 | E594: =SUMIFS($E$6:$E$582,$C$6:$C$582,$C594) -> 955.74 | G594: =SUMIFS($G$6:$G$582,$C$6:$C$582,$C594) -> 135415 | I594: =SUMIFS($I$6:$I$582,$C$6:$C$582,$C594) -> 12529 | J594: {=IFERROR(I594/G594*100,0)} -> 9.2522985 | K594: =SUMIFS($K$6:$K$582,$C$6:$C$582,$C594) -> 937 | L594: =IFERROR(K594/I594*100,0) -> 7.4786495 | M594: =IF(L594>2,"Perlu Pengendalian",IF(L594>0,"Tidak Perlu Pengendalian","Belum Sensus")) -> Perlu Pengendalian
... A600: LS II | B600: IV | C600: XVIII | D600: {=COUNTIFS($C$6:$C$582,$C600)} -> 27 | E600: =SUMIFS($E$6:$E$582,$C$6:$C$582,$C600) -> 857.16 | G600: =SUMIFS($G$6:$G$582,$C$6:$C$582,$C600) -> 114956 | I600: =SUMIFS($I$6:$I$582,$C$6:$C$582,$C600) -> 10647 | J600: {=IFERROR(I600/G600*100,0)} -> 9.2618045 | K600: =SUMIFS($K$6:$K$582,$C$6:$C$582,$C600) -> 956 | L600: =IFERROR(K600/I600*100,0) -> 8.9790551 | M600: =IF(L600>2,"Perlu Pengendalian",IF(L600>0,"Tidak Perlu Pengendalian","Belum Sensus")) -> Perlu Pengendalian
A601: LS I | B601: RAYON A | C601: RAYON A | D601: =SUM(D583:D585) -> 89 | E601: =SUM(E583:E585) -> 2864.33 | G601: =SUM(G583:G585) -> 384480 | I601: =SUM(I583:I585) -> 37863 | J601: {=IFERROR(I601/G601*100,0)} -> 9.8478464 | K601: =SUM(K583:K585) -> 4683 | L601: =IFERROR(K601/I601*100,0) -> 12.368275 | M601: =IF(L601>2,"Perlu Pengendalian",IF(L601>0,"Tidak Perlu Pengendalian","Belum Sensus")) -> Perlu Pengendalian
A602: LS I | B602: RAYON B | C602: RAYON B | D602: =SUM(D586:D587) -> 63 | E602: =SUM(E586:E587) -> 1859.87 | G602: =SUM(G586:G587) -> 266316 | I602: =SUM(I586:I587) -> 27092 | J602: {=IFERROR(I602/G602*100,0)} -> 10.172877 | K602: =SUM(K586:K587) -> 3276 | L602: =IFERROR(K602/I602*100,0) -> 12.092131 | M602: =IF(L602>2,"Perlu Pengendalian",IF(L602>0,"Tidak Perlu Pengendalian","Belum Sensus")) -> Perlu Pengendalian
A603: LS I | B603: RAYON C | C603: RAYON C | D603: =SUM(D588:D589) -> 77 | E603: =SUM(E588:E589) -> 2081.2 | G603: =SUM(G588:G589) -> 298441 | I603: =SUM(I588:I589) -> 28429 | J603: {=IFERROR(I603/G603*100,0)} -> 9.5258359 | K603: =SUM(K588:K589) -> 2095 | L603: =IFERROR(K603/I603*100,0) -> 7.3692356 | M603: =IF(L603>2,"Perlu Pengendalian",IF(L603>0,"Tidak Perlu Pengendalian","Belum Sensus")) -> Perlu Pengendalian
A604: LS I | B604: RAYON D | C604: RAYON D | D604: =SUM(D590:D591) -> 68 | E604: =SUM(E590:E591) -> 1858.7 | G604: =SUM(G590:G591) -> 269340 | I604: =SUM(I590:I591) -> 26825 | J604: {=IFERROR(I604/G604*100,0)} -> 9.9595307 | K604: =SUM(K590:K591) -> 2775 | L604: =IFERROR(K604/I604*100,0) -> 10.344828 | M604: =IF(L604>2,"Perlu Pengendalian",IF(L604>0,"Tidak Perlu Pengendalian","Belum Sensus")) -> Perlu Pengendalian
A605: LS II | B605: RAYON E | C605: RAYON E | D605: =SUM(D592:D594) -> 89 | E605: =SUM(E592:E594) -> 2517.03 | G605: =SUM(G592:G594) -> 352428 | I605: =SUM(I592:I594) -> 33491 | J605: {=IFERROR(I605/G605*100,0)} -> 9.5029339 | K605: =SUM(K592:K594) -> 4106 | L605: =IFERROR(K605/I605*100,0) -> 12.26001 | M605: =IF(L605>2,"Perlu Pengendalian",IF(L605>0,"Tidak Perlu Pengendalian","Belum Sensus")) -> Perlu Pengendalian
A606: LS II | B606: RAYON F | C606: RAYON F | D606: =SUM(D595:D596) -> 68 | E606: =SUM(E595:E596) -> 1924.9 | G606: =SUM(G594:G595) -> 277145 | I606: =SUM(I595:I596) -> 29301 | J606: {=IFERROR(I606/G606*100,0)} -> 10.572444 | K606: =SUM(K595:K596) -> 3471 | L606: =IFERROR(K606/I606*100,0) -> 11.846012 | M606: =IF(L606>2,"Perlu Pengendalian",IF(L606>0,"Tidak Perlu Pengendalian","Belum Sensus")) -> Perlu Pengendalian
A607: LS II | B607: RAYON G | C607: RAYON G | D607: =SUM(D597:D598) -> 63 | E607: =SUM(E597:E598) -> 1844.89 | G607: =SUM(G597:G598) -> 264202 | I607: =SUM(I597:I598) -> 24574 | J607: {=IFERROR(I607/G607*100,0)} -> 9.3012165 | K607: =SUM(K597:K598) -> 4705 | L607: =IFERROR(K607/I607*100,0) -> 19.146252 | M607: =IF(L607>2,"Perlu Pengendalian",IF(L607>0,"Tidak Perlu Pengendalian","Belum Sensus")) -> Perlu Pengendalian
A608: LS II | B608: RAYON H | C608: RAYON H | D608: =SUM(D599:D600) -> 60 | E608: =SUM(E599:E600) -> 1791.01 | G608: =SUM(G599:G600) -> 245050 | I608: =SUM(I599:I600) -> 23026 | J608: {=IFERROR(I608/G608*100,0)} -> 9.3964497 | K608: =SUM(K599:K600) -> 2599 | L608: =IFERROR(K608/I608*100,0) -> 11.287241 | M608: =IF(L608>2,"Perlu Pengendalian",IF(L608>0,"Tidak Perlu Pengendalian","Belum Sensus")) -> Perlu Pengendalian
A609: LS I | B609: I | C609: I | D609: {=SUMIFS($E$583:$E$600,$C$583:$C$600,$C609)} -> 922.58 | E609: =SUM(E601:F602) -> 4724.2 | G609: =SUM(G601:G602) -> 650796 | I609: =SUM(I601:I602) -> 64955 | J609: {=IFERROR(I609/G609*100,0)} -> 9.9808542 | K609: =SUM(K601:K602) -> 7959 | L609: =IFERROR(K609/I609*100,0) -> 12.253098 | M609: =IF(L609>2,"Perlu Pengendalian",IF(L609>0,"Tidak Perlu Pengendalian","Belum Sensus")) -> Perlu Pengendalian
A610: LS I | B610: II | C610: II | D610: {=SUMIFS($E$583:$E$600,$C$583:$C$600,$C610)} -> 1001.28 | E610: =SUM(E603:F604) -> 3939.9 | G610: =SUM(G603:G604) -> 567781 | I610: =SUM(I603:I604) -> 55254 | J610: {=IFERROR(I610/G610*100,0)} -> 9.731569 | K610: =SUM(K603:K604) -> 4870 | L610: =IFERROR(K610/I610*100,0) -> 8.8138415 | M610: =IF(L610>2,"Perlu Pengendalian",IF(L610>0,"Tidak Perlu Pengendalian","Belum Sensus")) -> Perlu Pengendalian
A611: LS II | B611: III | C611: III | D611: {=SUMIFS($E$583:$E$600,$C$583:$C$600,$C611)} -> 940.47 | E611: =SUM(E605:F606) -> 4441.93 | G611: =SUM(G605:G606) -> 629573 | I611: =SUM(I605:I606) -> 62792 | J611: {=IFERROR(I611/G611*100,0)} -> 9.9737441 | K611: =SUM(K605:K606) -> 7577 | L611: =IFERROR(K611/I611*100,0) -> 12.066824 | M611: =IF(L611>2,"Perlu Pengendalian",IF(L611>0,"Tidak Perlu Pengendalian","Belum Sensus")) -> Perlu Pengendalian
A612: LS II | B612: IV | C612: IV | D612: {=SUMIFS($E$583:$E$600,$C$583:$C$600,$C612)} -> 961 | E612: =SUM(E607:F608) -> 3635.9 | G612: =SUM(G607:G608) -> 509252 | I612: =SUM(I607:I608) -> 47600 | J612: {=IFERROR(I612/G612*100,0)} -> 9.3470423 | K612: =SUM(K607:K608) -> 7304 | L612: =IFERROR(K612/I612*100,0) -> 15.344538 | M612: =IF(L612>2,"Perlu Pengendalian",IF(L612>0,"Tidak Perlu Pengendalian","Belum Sensus")) -> Perlu Pengendalian
...

Sheet LS (Deteksi)
H1: 1 - 15 Agustus 2026
A2: Laporan Blok Yang Sudah Dikerjakan dan Blok InProgress Deteksi Tikus | H2: AKP + Grading | N2: AKP | V2: Grading TPH
A3: Kebun | B3: Est | C3: Afd | D3: Blok | E3: Luas (Ha) | F3: Jenis Tanah | G3: Total Pokok Produktif | H3: Tanggal Sensus | I3: Pokok Sensus/TBS Sensus | J3: Pokok Sensus (%) | K3: Pokok Terserang (Baru) | L3: % | M3: Rekomendasi | N3: Tanggal Sensus | O3: Pokok Sensus | P3: Pokok Sensus (%) | Q3: Pokok Terserang (Baru) | R3: % | S3: Rekomendasi | T3: Pokok Terserang (Lama) | U3: % | V3: Tanggal Sensus | W3: Jumlah TBS | X3: TBS Terserang (Baru) | Y3: % | Z3: Rekomendasi | AA3: Pokok Terserang (Lama) | AB3: %
A6: LS I | B6: I | C6: I | D6: B05 | E6: 29.32 | F6: GAMBUT | G6: 3615 | H6: =IF(N6>0,N6,V6) -> 0 | I6: =IF(O6>0,O6,W6) -> 0 | J6: =IF(P6>0,P6," ") | K6: =IF(Q6>0,Q6,X6) -> 0 | L6: =IFERROR(K6/I6*100,0) -> 0 | M6: {=IF(L6>5,"Perlu Sensus",IF(AND(L6>=0,I6>0),"Tetap Deteksi","Belum Deteksi"))} -> Belum Deteksi | N6: {=INDEX('[20]LS (Deteksi) Agustus'!N$7:N$303,MATCH(1,('[20]LS (Deteksi) Agustus'!$D$7:$D$303=$D6)*('[20]LS (Deteksi) Agustus'!$D$7:$D$303=$D6),0))} -> 0 | O6: {=INDEX('[20]LS (Deteksi) Agustus'!O$7:O$303,MATCH(1,('[20]LS (Deteksi) Agustus'!$D$7:$D$303=$D6)*('[20]LS (Deteksi) Agustus'!$D$7:$D$303=$D6),0))} -> 0 | P6: {=IFERROR(O6/G6*100,0)} -> 0 | Q6: {=INDEX('[20]LS (Deteksi) Agustus'!Q$7:Q$303,MATCH(1,('[20]LS (Deteksi) Agustus'!$D$7:$D$303=$D6)*('[20]LS (Deteksi) Agustus'!$D$7:$D$303=$D6),0))} -> 0 | R6: =IFERROR(Q6/O6*100,0) -> 0 | S6: {=IF(R6>5,"Perlu Sensus",IF(AND(R6>=0,O6>0),"Tetap Deteksi","Belum Deteksi"))} -> Belum Deteksi | T6: {=INDEX('[20]LS (Deteksi) Agustus'!T$7:T$303,MATCH(1,('[20]LS (Deteksi) Agustus'!$D$7:$D$303=$D6)*('[20]LS (Deteksi) Agustus'!$D$7:$D$303=$D6),0))} -> 0 | U6: =IFERROR(T6/O6*100,0) -> 0 | V6: {=INDEX('[20]LS (Deteksi) Agustus'!V$7:V$303,MATCH(1,('[20]LS (Deteksi) Agustus'!$D$7:$D$303=$D6)*('[20]LS (Deteksi) Agustus'!$D$7:$D$303=$D6),0))} -> 0 | W6: {=INDEX('[20]LS (Deteksi) Agustus'!W$7:W$303,MATCH(1,('[20]LS (Deteksi) Agustus'!$D$7:$D$303=$D6)*('[20]LS (Deteksi) Agustus'!$D$7:$D$303=$D6),0))} -> 0 | X6: {=INDEX('[20]LS (Deteksi) Agustus'!X$7:X$303,MATCH(1,('[20]LS (Deteksi) Agustus'!$D$7:$D$303=$D6)*('[20]LS (Deteksi) Agustus'!$D$7:$D$303=$D6),0))} -> 0 | Y6: =IFERROR(X6/W6*100,0) -> 0 | Z6: {=IF(Y6>5,"Perlu Sensus",IF(AND(Y6>0,,O6>0),"Tetap Deteksi","Belum Deteksi"))} -> Belum Deteksi | AA6: {=INDEX('[20]LS (Deteksi) Agustus'!AA$7:AA$303,MATCH(1,('[20]LS (Deteksi) Agustus'!$D$7:$D$303=$D6)*('[20]LS (Deteksi) Agustus'!$D$7:$D$303=$D6),0))} -> 0 | AB6: =IFERROR(AA6/W6*100,0) -> 0
A7: LS I | B7: I | C7: I | D7: B06 | E7: 22.39 | F7: GAMBUT | G7: 3145 | H7: =IF(N7>0,N7,V7) -> 0 | I7: =IF(O7>0,O7,W7) -> 0 | J7: =IF(P7>0,P7," ") | K7: =IF(Q7>0,Q7,X7) -> 0 | L7: =IFERROR(K7/I7*100,0) -> 0 | M7: {=IF(L7>5,"Perlu Sensus",IF(AND(L7>=0,I7>0),"Tetap Deteksi","Belum Deteksi"))} -> Belum Deteksi | N7: {=INDEX('[20]LS (Deteksi) Agustus'!N$7:N$303,MATCH(1,('[20]LS (Deteksi) Agustus'!$D$7:$D$303=$D7)*('[20]LS (Deteksi) Agustus'!$D$7:$D$303=$D7),0))} -> 0 | O7: {=INDEX('[20]LS (Deteksi) Agustus'!O$7:O$303,MATCH(1,('[20]LS (Deteksi) Agustus'!$D$7:$D$303=$D7)*('[20]LS (Deteksi) Agustus'!$D$7:$D$303=$D7),0))} -> 0 | P7: {=IFERROR(O7/G7*100,0)} -> 0 | Q7: {=INDEX('[20]LS (Deteksi) Agustus'!Q$7:Q$303,MATCH(1,('[20]LS (Deteksi) Agustus'!$D$7:$D$303=$D7)*('[20]LS (Deteksi) Agustus'!$D$7:$D$303=$D7),0))} -> 0 | R7: =IFERROR(Q7/O7*100,0) -> 0 | S7: {=IF(R7>5,"Perlu Sensus",IF(AND(R7>=0,O7>0),"Tetap Deteksi","Belum Deteksi"))} -> Belum Deteksi | T7: {=INDEX('[20]LS (Deteksi) Agustus'!T$7:T$303,MATCH(1,('[20]LS (Deteksi) Agustus'!$D$7:$D$303=$D7)*('[20]LS (Deteksi) Agustus'!$D$7:$D$303=$D7),0))} -> 0 | U7: =IFERROR(T7/O7*100,0) -> 0 | V7: {=INDEX('[20]LS (Deteksi) Agustus'!V$7:V$303,MATCH(1,('[20]LS (Deteksi) Agustus'!$D$7:$D$303=$D7)*('[20]LS (Deteksi) Agustus'!$D$7:$D$303=$D7),0))} -> 0 | W7: {=INDEX('[20]LS (Deteksi) Agustus'!W$7:W$303,MATCH(1,('[20]LS (Deteksi) Agustus'!$D$7:$D$303=$D7)*('[20]LS (Deteksi) Agustus'!$D$7:$D$303=$D7),0))} -> 0 | X7: {=INDEX('[20]LS (Deteksi) Agustus'!X$7:X$303,MATCH(1,('[20]LS (Deteksi) Agustus'!$D$7:$D$303=$D7)*('[20]LS (Deteksi) Agustus'!$D$7:$D$303=$D7),0))} -> 0 | Y7: =IFERROR(X7/W7*100,0) -> 0 | Z7: {=IF(Y7>5,"Perlu Sensus",IF(AND(Y7>0,,O7>0),"Tetap Deteksi","Belum Deteksi"))} -> Belum Deteksi | AA7: {=INDEX('[20]LS (Deteksi) Agustus'!AA$7:AA$303,MATCH(1,('[20]LS (Deteksi) Agustus'!$D$7:$D$303=$D7)*('[20]LS (Deteksi) Agustus'!$D$7:$D$303=$D7),0))} -> 0 | AB7: =IFERROR(AA7/W7*100,0) -> 0
A8: LS I | B8: I | C8: I | D8: B07 | E8: 25.74 | F8: GAMBUT | G8: 3551 | H8: =IF(N8>0,N8,V8) -> 46244 | I8: =IF(O8>0,O8,W8) -> 78 | J8: =IF(P8>0,P8," ") -> 2.1965643 | K8: =IF(Q8>0,Q8,X8) -> 3 | L8: =IFERROR(K8/I8*100,0) -> 3.8461538 | M8: {=IF(L8>5,"Perlu Sensus",IF(AND(L8>=0,I8>0),"Tetap Deteksi","Belum Deteksi"))} -> Tetap Deteksi | N8: {=INDEX('[20]LS (Deteksi) Agustus'!N$7:N$303,MATCH(1,('[20]LS (Deteksi) Agustus'!$D$7:$D$303=$D8)*('[20]LS (Deteksi) Agustus'!$D$7:$D$303=$D8),0))} -> 46244 | O8: {=INDEX('[20]LS (Deteksi) Agustus'!O$7:O$303,MATCH(1,('[20]LS (Deteksi) Agustus'!$D$7:$D$303=$D8)*('[20]LS (Deteksi) Agustus'!$D$7:$D$303=$D8),0))} -> 78 | P8: {=IFERROR(O8/G8*100,0)} -> 2.1965643 | Q8: {=INDEX('[20]LS (Deteksi) Agustus'!Q$7:Q$303,MATCH(1,('[20]LS (Deteksi) Agustus'!$D$7:$D$303=$D8)*('[20]LS (Deteksi) Agustus'!$D$7:$D$303=$D8),0))} -> 3 | R8: =IFERROR(Q8/O8*100,0) -> 3.8461538 | S8: {=IF(R8>5,"Perlu Sensus",IF(AND(R8>=0,O8>0),"Tetap Deteksi","Belum Deteksi"))} -> Tetap Deteksi | T8: {=INDEX('[20]LS (Deteksi) Agustus'!T$7:T$303,MATCH(1,('[20]LS (Deteksi) Agustus'!$D$7:$D$303=$D8)*('[20]LS (Deteksi) Agustus'!$D$7:$D$303=$D8),0))} -> 5 | U8: =IFERROR(T8/O8*100,0) -> 6.4102564 | V8: {=INDEX('[20]LS (Deteksi) Agustus'!V$7:V$303,MATCH(1,('[20]LS (Deteksi) Agustus'!$D$7:$D$303=$D8)*('[20]LS (Deteksi) Agustus'!$D$7:$D$303=$D8),0))} -> 46245 | W8: {=INDEX('[20]LS (Deteksi) Agustus'!W$7:W$303,MATCH(1,('[20]LS (Deteksi) Agustus'!$D$7:$D$303=$D8)*('[20]LS (Deteksi) Agustus'!$D$7:$D$303=$D8),0))} -> 189 | X8: {=INDEX('[20]LS (Deteksi) Agustus'!X$7:X$303,MATCH(1,('[20]LS (Deteksi) Agustus'!$D$7:$D$303=$D8)*('[20]LS (Deteksi) Agustus'!$D$7:$D$303=$D8),0))} -> 4 | Y8: =IFERROR(X8/W8*100,0) -> 2.1164021 | Z8: {=IF(Y8>5,"Perlu Sensus",IF(AND(Y8>0,,O8>0),"Tetap Deteksi","Belum Deteksi"))} -> Belum Deteksi | AA8: {=INDEX('[20]LS (Deteksi) Agustus'!AA$7:AA$303,MATCH(1,('[20]LS (Deteksi) Agustus'!$D$7:$D$303=$D8)*('[20]LS (Deteksi) Agustus'!$D$7:$D$303=$D8),0))} -> 13 | AB8: =IFERROR(AA8/W8*100,0) -> 6.8783069
A9: LS I | B9: I | C9: I | D9: B08 | E9: 29.3 | F9: GAMBUT | G9: 4705 | H9: =IF(N9>0,N9,V9) -> 46244 | I9: =IF(O9>0,O9,W9) -> 54 | J9: =IF(P9>0,P9," ") -> 1.1477152 | K9: =IF(Q9>0,Q9,X9) -> 3 | L9: =IFERROR(K9/I9*100,0) -> 5.5555556 | M9: {=IF(L9>5,"Perlu Sensus",IF(AND(L9>=0,I9>0),"Tetap Deteksi","Belum Deteksi"))} -> Perlu Sensus | N9: {=INDEX('[20]LS (Deteksi) Agustus'!N$7:N$303,MATCH(1,('[20]LS (Deteksi) Agustus'!$D$7:$D$303=$D9)*('[20]LS (Deteksi) Agustus'!$D$7:$D$303=$D9),0))} -> 46244 | O9: {=INDEX('[20]LS (Deteksi) Agustus'!O$7:O$303,MATCH(1,('[20]LS (Deteksi) Agustus'!$D$7:$D$303=$D9)*('[20]LS (Deteksi) Agustus'!$D$7:$D$303=$D9),0))} -> 54 | P9: {=IFERROR(O9/G9*100,0)} -> 1.1477152 | Q9: {=INDEX('[20]LS (Deteksi) Agustus'!Q$7:Q$303,MATCH(1,('[20]LS (Deteksi) Agustus'!$D$7:$D$303=$D9)*('[20]LS (Deteksi) Agustus'!$D$7:$D$303=$D9),0))} -> 3 | R9: =IFERROR(Q9/O9*100,0) -> 5.5555556 | S9: {=IF(R9>5,"Perlu Sensus",IF(AND(R9>=0,O9>0),"Tetap Deteksi","Belum Deteksi"))} -> Perlu Sensus | T9: {=INDEX('[20]LS (Deteksi) Agustus'!T$7:T$303,MATCH(1,('[20]LS (Deteksi) Agustus'!$D$7:$D$303=$D9)*('[20]LS (Deteksi) Agustus'!$D$7:$D$303=$D9),0))} -> 18 | U9: =IFERROR(T9/O9*100,0) -> 33.333333 | V9: {=INDEX('[20]LS (Deteksi) Agustus'!V$7:V$303,MATCH(1,('[20]LS (Deteksi) Agustus'!$D$7:$D$303=$D9)*('[20]LS (Deteksi) Agustus'!$D$7:$D$303=$D9),0))} -> 46245 | W9: {=INDEX('[20]LS (Deteksi) Agustus'!W$7:W$303,MATCH(1,('[20]LS (Deteksi) Agustus'!$D$7:$D$303=$D9)*('[20]LS (Deteksi) Agustus'!$D$7:$D$303=$D9),0))} -> 210 | X9: {=INDEX('[20]LS (Deteksi) Agustus'!X$7:X$303,MATCH(1,('[20]LS (Deteksi) Agustus'!$D$7:$D$303=$D9)*('[20]LS (Deteksi) Agustus'!$D$7:$D$303=$D9),0))} -> 6 | Y9: =IFERROR(X9/W9*100,0) -> 2.8571429 | Z9: {=IF(Y9>5,"Perlu Sensus",IF(AND(Y9>0,,O9>0),"Tetap Deteksi","Belum Deteksi"))} -> Belum Deteksi | AA9: {=INDEX('[20]LS (Deteksi) Agustus'!AA$7:AA$303,MATCH(1,('[20]LS (Deteksi) Agustus'!$D$7:$D$303=$D9)*('[20]LS (Deteksi) Agustus'!$D$7:$D$303=$D9),0))} -> 16 | AB9: =IFERROR(AA9/W9*100,0) -> 7.6190476
A10: LS I | B10: I | C10: I | D10: B09 | E10: 31.12 | F10: GAMBUT | G10: 4836 | H10: =IF(N10>0,N10,V10) -> 46247 | I10: =IF(O10>0,O10,W10) -> 176 | J10: =IF(P10>0,P10," ") | K10: =IF(Q10>0,Q10,X10) -> 9 | L10: =IFERROR(K10/I10*100,0) -> 5.1136364 | M10: {=IF(L10>5,"Perlu Sensus",IF(AND(L10>=0,I10>0),"Tetap Deteksi","Belum Deteksi"))} -> Perlu Sensus | N10: {=INDEX('[20]LS (Deteksi) Agustus'!N$7:N$303,MATCH(1,('[20]LS (Deteksi) Agustus'!$D$7:$D$303=$D10)*('[20]LS (Deteksi) Agustus'!$D$7:$D$303=$D10),0))} -> 0 | O10: {=INDEX('[20]LS (Deteksi) Agustus'!O$7:O$303,MATCH(1,('[20]LS (Deteksi) Agustus'!$D$7:$D$303=$D10)*('[20]LS (Deteksi) Agustus'!$D$7:$D$303=$D10),0))} -> 0 | P10: {=IFERROR(O10/G10*100,0)} -> 0 | Q10: {=INDEX('[20]LS (Deteksi) Agustus'!Q$7:Q$303,MATCH(1,('[20]LS (Deteksi) Agustus'!$D$7:$D$303=$D10)*('[20]LS (Deteksi) Agustus'!$D$7:$D$303=$D10),0))} -> 0 | R10: =IFERROR(Q10/O10*100,0) -> 0 | S10: {=IF(R10>5,"Perlu Sensus",IF(AND(R10>=0,O10>0),"Tetap Deteksi","Belum Deteksi"))} -> Belum Deteksi | T10: {=INDEX('[20]LS (Deteksi) Agustus'!T$7:T$303,MATCH(1,('[20]LS (Deteksi) Agustus'!$D$7:$D$303=$D10)*('[20]LS (Deteksi) Agustus'!$D$7:$D$303=$D10),0))} -> 0 | U10: =IFERROR(T10/O10*100,0) -> 0 | V10: {=INDEX('[20]LS (Deteksi) Agustus'!V$7:V$303,MATCH(1,('[20]LS (Deteksi) Agustus'!$D$7:$D$303=$D10)*('[20]LS (Deteksi) Agustus'!$D$7:$D$303=$D10),0))} -> 46247 | W10: {=INDEX('[20]LS (Deteksi) Agustus'!W$7:W$303,MATCH(1,('[20]LS (Deteksi) Agustus'!$D$7:$D$303=$D10)*('[20]LS (Deteksi) Agustus'!$D$7:$D$303=$D10),0))} -> 176 | X10: {=INDEX('[20]LS (Deteksi) Agustus'!X$7:X$303,MATCH(1,('[20]LS (Deteksi) Agustus'!$D$7:$D$303=$D10)*('[20]LS (Deteksi) Agustus'!$D$7:$D$303=$D10),0))} -> 9 | Y10: =IFERROR(X10/W10*100,0) -> 5.1136364 | Z10: {=IF(Y10>5,"Perlu Sensus",IF(AND(Y10>0,,O10>0),"Tetap Deteksi","Belum Deteksi"))} -> Perlu Sensus | AA10: {=INDEX('[20]LS (Deteksi) Agustus'!AA$7:AA$303,MATCH(1,('[20]LS (Deteksi) Agustus'!$D$7:$D$303=$D10)*('[20]LS (Deteksi) Agustus'!$D$7:$D$303=$D10),0))} -> 17 | AB10: =IFERROR(AA10/W10*100,0) -> 9.6590909
A11: LS I | B11: I | C11: I | D11: B10 | E11: 36.85 | F11: GAMBUT | G11: 5351 | H11: =IF(N11>0,N11,V11) -> 46247 | I11: =IF(O11>0,O11,W11) -> 219 | J11: =IF(P11>0,P11," ") | K11: =IF(Q11>0,Q11,X11) -> 12 | L11: =IFERROR(K11/I11*100,0) -> 5.4794521 | M11: {=IF(L11>5,"Perlu Sensus",IF(AND(L11>=0,I11>0),"Tetap Deteksi","Belum Deteksi"))} -> Perlu Sensus | N11: {=INDEX('[20]LS (Deteksi) Agustus'!N$7:N$303,MATCH(1,('[20]LS (Deteksi) Agustus'!$D$7:$D$303=$D11)*('[20]LS (Deteksi) Agustus'!$D$7:$D$303=$D11),0))} -> 0 | O11: {=INDEX('[20]LS (Deteksi) Agustus'!O$7:O$303,MATCH(1,('[20]LS (Deteksi) Agustus'!$D$7:$D$303=$D11)*('[20]LS (Deteksi) Agustus'!$D$7:$D$303=$D11),0))} -> 0 | P11: {=IFERROR(O11/G11*100,0)} -> 0 | Q11: {=INDEX('[20]LS (Deteksi) Agustus'!Q$7:Q$303,MATCH(1,('[20]LS (Deteksi) Agustus'!$D$7:$D$303=$D11)*('[20]LS (Deteksi) Agustus'!$D$7:$D$303=$D11),0))} -> 0 | R11: =IFERROR(Q11/O11*100,0) -> 0 | S11: {=IF(R11>5,"Perlu Sensus",IF(AND(R11>=0,O11>0),"Tetap Deteksi","Belum Deteksi"))} -> Belum Deteksi | T11: {=INDEX('[20]LS (Deteksi) Agustus'!T$7:T$303,MATCH(1,('[20]LS (Deteksi) Agustus'!$D$7:$D$303=$D11)*('[20]LS (Deteksi) Agustus'!$D$7:$D$303=$D11),0))} -> 0 | U11: =IFERROR(T11/O11*100,0) -> 0 | V11: {=INDEX('[20]LS (Deteksi) Agustus'!V$7:V$303,MATCH(1,('[20]LS (Deteksi) Agustus'!$D$7:$D$303=$D11)*('[20]LS (Deteksi) Agustus'!$D$7:$D$303=$D11),0))} -> 46247 | W11: {=INDEX('[20]LS (Deteksi) Agustus'!W$7:W$303,MATCH(1,('[20]LS (Deteksi) Agustus'!$D$7:$D$303=$D11)*('[20]LS (Deteksi) Agustus'!$D$7:$D$303=$D11),0))} -> 219 | X11: {=INDEX('[20]LS (Deteksi) Agustus'!X$7:X$303,MATCH(1,('[20]LS (Deteksi) Agustus'!$D$7:$D$303=$D11)*('[20]LS (Deteksi) Agustus'!$D$7:$D$303=$D11),0))} -> 12 | Y11: =IFERROR(X11/W11*100,0) -> 5.4794521 | Z11: {=IF(Y11>5,"Perlu Sensus",IF(AND(Y11>0,,O11>0),"Tetap Deteksi","Belum Deteksi"))} -> Perlu Sensus | AA11: {=INDEX('[20]LS (Deteksi) Agustus'!AA$7:AA$303,MATCH(1,('[20]LS (Deteksi) Agustus'!$D$7:$D$303=$D11)*('[20]LS (Deteksi) Agustus'!$D$7:$D$303=$D11),0))} -> 19 | AB11: =IFERROR(AA11/W11*100,0) -> 8.6757991
A12: LS I | B12: I | C12: I | D12: B11 | E12: 31.93 | F12: GAMBUT | G12: 4122 | H12: =IF(N12>0,N12,V12) -> 46248 | I12: =IF(O12>0,O12,W12) -> 176 | J12: =IF(P12>0,P12," ") | K12: =IF(Q12>0,Q12,X12) -> 5 | L12: =IFERROR(K12/I12*100,0) -> 2.8409091 | M12: {=IF(L12>5,"Perlu Sensus",IF(AND(L12>=0,I12>0),"Tetap Deteksi","Belum Deteksi"))} -> Tetap Deteksi | N12: {=INDEX('[20]LS (Deteksi) Agustus'!N$7:N$303,MATCH(1,('[20]LS (Deteksi) Agustus'!$D$7:$D$303=$D12)*('[20]LS (Deteksi) Agustus'!$D$7:$D$303=$D12),0))} -> 0 | O12: {=INDEX('[20]LS (Deteksi) Agustus'!O$7:O$303,MATCH(1,('[20]LS (Deteksi) Agustus'!$D$7:$D$303=$D12)*('[20]LS (Deteksi) Agustus'!$D$7:$D$303=$D12),0))} -> 0 | P12: {=IFERROR(O12/G12*100,0)} -> 0 | Q12: {=INDEX('[20]LS (Deteksi) Agustus'!Q$7:Q$303,MATCH(1,('[20]LS (Deteksi) Agustus'!$D$7:$D$303=$D12)*('[20]LS (Deteksi) Agustus'!$D$7:$D$303=$D12),0))} -> 0 | R12: =IFERROR(Q12/O12*100,0) -> 0 | S12: {=IF(R12>5,"Perlu Sensus",IF(AND(R12>=0,O12>0),"Tetap Deteksi","Belum Deteksi"))} -> Belum Deteksi | T12: {=INDEX('[20]LS (Deteksi) Agustus'!T$7:T$303,MATCH(1,('[20]LS (Deteksi) Agustus'!$D$7:$D$303=$D12)*('[20]LS (Deteksi) Agustus'!$D$7:$D$303=$D12),0))} -> 0 | U12: =IFERROR(T12/O12*100,0) -> 0 | V12: {=INDEX('[20]LS (Deteksi) Agustus'!V$7:V$303,MATCH(1,('[20]LS (Deteksi) Agustus'!$D$7:$D$303=$D12)*('[20]LS (Deteksi) Agustus'!$D$7:$D$303=$D12),0))} -> 46248 | W12: {=INDEX('[20]LS (Deteksi) Agustus'!W$7:W$303,MATCH(1,('[20]LS (Deteksi) Agustus'!$D$7:$D$303=$D12)*('[20]LS (Deteksi) Agustus'!$D$7:$D$303=$D12),0))} -> 176 | X12: {=INDEX('[20]LS (Deteksi) Agustus'!X$7:X$303,MATCH(1,('[20]LS (Deteksi) Agustus'!$D$7:$D$303=$D12)*('[20]LS (Deteksi) Agustus'!$D$7:$D$303=$D12),0))} -> 5 | Y12: =IFERROR(X12/W12*100,0) -> 2.8409091 | Z12: {=IF(Y12>5,"Perlu Sensus",IF(AND(Y12>0,,O12>0),"Tetap Deteksi","Belum Deteksi"))} -> Belum Deteksi | AA12: {=INDEX('[20]LS (Deteksi) Agustus'!AA$7:AA$303,MATCH(1,('[20]LS (Deteksi) Agustus'!$D$7:$D$303=$D12)*('[20]LS (Deteksi) Agustus'!$D$7:$D$303=$D12),0))} -> 10 | AB12: =IFERROR(AA12/W12*100,0) -> 5.6818182
A13: LS I | B13: I | C13: I | D13: B12 | E13: 37.13 | F13: GAMBUT | G13: 4726 | H13: =IF(N13>0,N13,V13) -> 46248 | I13: =IF(O13>0,O13,W13) -> 180 | J13: =IF(P13>0,P13," ") | K13: =IF(Q13>0,Q13,X13) -> 8 | L13: =IFERROR(K13/I13*100,0) -> 4.4444444 | M13: {=IF(L13>5,"Perlu Sensus",IF(AND(L13>=0,I13>0),"Tetap Deteksi","Belum Deteksi"))} -> Tetap Deteksi | N13: {=INDEX('[20]LS (Deteksi) Agustus'!N$7:N$303,MATCH(1,('[20]LS (Deteksi) Agustus'!$D$7:$D$303=$D13)*('[20]LS (Deteksi) Agustus'!$D$7:$D$303=$D13),0))} -> 0 | O13: {=INDEX('[20]LS (Deteksi) Agustus'!O$7:O$303,MATCH(1,('[20]LS (Deteksi) Agustus'!$D$7:$D$303=$D13)*('[20]LS (Deteksi) Agustus'!$D$7:$D$303=$D13),0))} -> 0 | P13: {=IFERROR(O13/G13*100,0)} -> 0 | Q13: {=INDEX('[20]LS (Deteksi) Agustus'!Q$7:Q$303,MATCH(1,('[20]LS (Deteksi) Agustus'!$D$7:$D$303=$D13)*('[20]LS (Deteksi) Agustus'!$D$7:$D$303=$D13),0))} -> 0 | R13: =IFERROR(Q13/O13*100,0) -> 0 | S13: {=IF(R13>5,"Perlu Sensus",IF(AND(R13>=0,O13>0),"Tetap Deteksi","Belum Deteksi"))} -> Belum Deteksi | T13: {=INDEX('[20]LS (Deteksi) Agustus'!T$7:T$303,MATCH(1,('[20]LS (Deteksi) Agustus'!$D$7:$D$303=$D13)*('[20]LS (Deteksi) Agustus'!$D$7:$D$303=$D13),0))} -> 0 | U13: =IFERROR(T13/O13*100,0) -> 0 | V13: {=INDEX('[20]LS (Deteksi) Agustus'!V$7:V$303,MATCH(1,('[20]LS (Deteksi) Agustus'!$D$7:$D$303=$D13)*('[20]LS (Deteksi) Agustus'!$D$7:$D$303=$D13),0))} -> 46248 | W13: {=INDEX('[20]LS (Deteksi) Agustus'!W$7:W$303,MATCH(1,('[20]LS (Deteksi) Agustus'!$D$7:$D$303=$D13)*('[20]LS (Deteksi) Agustus'!$D$7:$D$303=$D13),0))} -> 180 | X13: {=INDEX('[20]LS (Deteksi) Agustus'!X$7:X$303,MATCH(1,('[20]LS (Deteksi) Agustus'!$D$7:$D$303=$D13)*('[20]LS (Deteksi) Agustus'!$D$7:$D$303=$D13),0))} -> 8 | Y13: =IFERROR(X13/W13*100,0) -> 4.4444444 | Z13: {=IF(Y13>5,"Perlu Sensus",IF(AND(Y13>0,,O13>0),"Tetap Deteksi","Belum Deteksi"))} -> Belum Deteksi | AA13: {=INDEX('[20]LS (Deteksi) Agustus'!AA$7:AA$303,MATCH(1,('[20]LS (Deteksi) Agustus'!$D$7:$D$303=$D13)*('[20]LS (Deteksi) Agustus'!$D$7:$D$303=$D13),0))} -> 13 | AB13: =IFERROR(AA13/W13*100,0) -> 7.2222222
A14: LS I | B14: I | C14: I | D14: B13 | E14: 33.49 | F14: GAMBUT | G14: 3913 | H14: =IF(N14>0,N14,V14) -> 46248 | I14: =IF(O14>0,O14,W14) -> 187 | J14: =IF(P14>0,P14," ") -> 4.778942 | K14: =IF(Q14>0,Q14,X14) -> 11 | L14: =IFERROR(K14/I14*100,0) -> 5.8823529 | M14: {=IF(L14>5,"Perlu Sensus",IF(AND(L14>=0,I14>0),"Tetap Deteksi","Belum Deteksi"))} -> Perlu Sensus | N14: {=INDEX('[20]LS (Deteksi) Agustus'!N$7:N$303,MATCH(1,('[20]LS (Deteksi) Agustus'!$D$7:$D$303=$D14)*('[20]LS (Deteksi) Agustus'!$D$7:$D$303=$D14),0))} -> 46248 | O14: {=INDEX('[20]LS (Deteksi) Agustus'!O$7:O$303,MATCH(1,('[20]LS (Deteksi) Agustus'!$D$7:$D$303=$D14)*('[20]LS (Deteksi) Agustus'!$D$7:$D$303=$D14),0))} -> 187 | P14: {=IFERROR(O14/G14*100,0)} -> 4.778942 | Q14: {=INDEX('[20]LS (Deteksi) Agustus'!Q$7:Q$303,MATCH(1,('[20]LS (Deteksi) Agustus'!$D$7:$D$303=$D14)*('[20]LS (Deteksi) Agustus'!$D$7:$D$303=$D14),0))} -> 11 | R14: =IFERROR(Q14/O14*100,0) -> 5.8823529 | S14: {=IF(R14>5,"Perlu Sensus",IF(AND(R14>=0,O14>0),"Tetap Deteksi","Belum Deteksi"))} -> Perlu Sensus | T14: {=INDEX('[20]LS (Deteksi) Agustus'!T$7:T$303,MATCH(1,('[20]LS (Deteksi) Agustus'!$D$7:$D$303=$D14)*('[20]LS (Deteksi) Agustus'!$D$7:$D$303=$D14),0))} -> 16 | U14: =IFERROR(T14/O14*100,0) -> 8.5561497 | V14: {=INDEX('[20]LS (Deteksi) Agustus'!V$7:V$303,MATCH(1,('[20]LS (Deteksi) Agustus'!$D$7:$D$303=$D14)*('[20]LS (Deteksi) Agustus'!$D$7:$D$303=$D14),0))} -> 0 | W14: {=INDEX('[20]LS (Deteksi) Agustus'!W$7:W$303,MATCH(1,('[20]LS (Deteksi) Agustus'!$D$7:$D$303=$D14)*('[20]LS (Deteksi) Agustus'!$D$7:$D$303=$D14),0))} -> 0 | X14: {=INDEX('[20]LS (Deteksi) Agustus'!X$7:X$303,MATCH(1,('[20]LS (Deteksi) Agustus'!$D$7:$D$303=$D14)*('[20]LS (Deteksi) Agustus'!$D$7:$D$303=$D14),0))} -> 0 | Y14: =IFERROR(X14/W14*100,0) -> 0 | Z14: {=IF(Y14>5,"Perlu Sensus",IF(AND(Y14>0,,O14>0),"Tetap Deteksi","Belum Deteksi"))} -> Belum Deteksi | AA14: {=INDEX('[20]LS (Deteksi) Agustus'!AA$7:AA$303,MATCH(1,('[20]LS (Deteksi) Agustus'!$D$7:$D$303=$D14)*('[20]LS (Deteksi) Agustus'!$D$7:$D$303=$D14),0))} -> 0 | AB14: =IFERROR(AA14/W14*100,0) -> 0
A15: LS I | B15: I | C15: I | D15: B14 | E15: 29.45 | F15: GAMBUT | G15: 3806 | H15: =IF(N15>0,N15,V15) -> 46248 | I15: =IF(O15>0,O15,W15) -> 121 | J15: =IF(P15>0,P15," ") -> 3.1791908 | K15: =IF(Q15>0,Q15,X15) -> 8 | L15: =IFERROR(K15/I15*100,0) -> 6.6115702 | M15: {=IF(L15>5,"Perlu Sensus",IF(AND(L15>=0,I15>0),"Tetap Deteksi","Belum Deteksi"))} -> Perlu Sensus | N15: {=INDEX('[20]LS (Deteksi) Agustus'!N$7:N$303,MATCH(1,('[20]LS (Deteksi) Agustus'!$D$7:$D$303=$D15)*('[20]LS (Deteksi) Agustus'!$D$7:$D$303=$D15),0))} -> 46248 | O15: {=INDEX('[20]LS (Deteksi) Agustus'!O$7:O$303,MATCH(1,('[20]LS (Deteksi) Agustus'!$D$7:$D$303=$D15)*('[20]LS (Deteksi) Agustus'!$D$7:$D$303=$D15),0))} -> 121 | P15: {=IFERROR(O15/G15*100,0)} -> 3.1791908 | Q15: {=INDEX('[20]LS (Deteksi) Agustus'!Q$7:Q$303,MATCH(1,('[20]LS (Deteksi) Agustus'!$D$7:$D$303=$D15)*('[20]LS (Deteksi) Agustus'!$D$7:$D$303=$D15),0))} -> 8 | R15: =IFERROR(Q15/O15*100,0) -> 6.6115702 | S15: {=IF(R15>5,"Perlu Sensus",IF(AND(R15>=0,O15>0),"Tetap Deteksi","Belum Deteksi"))} -> Perlu Sensus | T15: {=INDEX('[20]LS (Deteksi) Agustus'!T$7:T$303,MATCH(1,('[20]LS (Deteksi) Agustus'!$D$7:$D$303=$D15)*('[20]LS (Deteksi) Agustus'!$D$7:$D$303=$D15),0))} -> 9 | U15: =IFERROR(T15/O15*100,0) -> 7.4380165 | V15: {=INDEX('[20]LS (Deteksi) Agustus'!V$7:V$303,MATCH(1,('[20]LS (Deteksi) Agustus'!$D$7:$D$303=$D15)*('[20]LS (Deteksi) Agustus'!$D$7:$D$303=$D15),0))} -> 0 | W15: {=INDEX('[20]LS (Deteksi) Agustus'!W$7:W$303,MATCH(1,('[20]LS (Deteksi) Agustus'!$D$7:$D$303=$D15)*('[20]LS (Deteksi) Agustus'!$D$7:$D$303=$D15),0))} -> 0 | X15: {=INDEX('[20]LS (Deteksi) Agustus'!X$7:X$303,MATCH(1,('[20]LS (Deteksi) Agustus'!$D$7:$D$303=$D15)*('[20]LS (Deteksi) Agustus'!$D$7:$D$303=$D15),0))} -> 0 | Y15: =IFERROR(X15/W15*100,0) -> 0 | Z15: {=IF(Y15>5,"Perlu Sensus",IF(AND(Y15>0,,O15>0),"Tetap Deteksi","Belum Deteksi"))} -> Belum Deteksi | AA15: {=INDEX('[20]LS (Deteksi) Agustus'!AA$7:AA$303,MATCH(1,('[20]LS (Deteksi) Agustus'!$D$7:$D$303=$D15)*('[20]LS (Deteksi) Agustus'!$D$7:$D$303=$D15),0))} -> 0 | AB15: =IFERROR(AA15/W15*100,0) -> 0
A16: LS I | B16: I | C16: I | D16: B15 | E16: 24.51 | F16: GAMBUT | G16: 3672 | H16: =IF(N16>0,N16,V16) -> 46241 | I16: =IF(O16>0,O16,W16) -> 54 | J16: =IF(P16>0,P16," ") -> 1.4705882 | K16: =IF(Q16>0,Q16,X16) -> 3 | L16: =IFERROR(K16/I16*100,0) -> 5.5555556 | M16: {=IF(L16>5,"Perlu Sensus",IF(AND(L16>=0,I16>0),"Tetap Deteksi","Belum Deteksi"))} -> Perlu Sensus | N16: {=INDEX('[20]LS (Deteksi) Agustus'!N$7:N$303,MATCH(1,('[20]LS (Deteksi) Agustus'!$D$7:$D$303=$D16)*('[20]LS (Deteksi) Agustus'!$D$7:$D$303=$D16),0))} -> 46241 | O16: {=INDEX('[20]LS (Deteksi) Agustus'!O$7:O$303,MATCH(1,('[20]LS (Deteksi) Agustus'!$D$7:$D$303=$D16)*('[20]LS (Deteksi) Agustus'!$D$7:$D$303=$D16),0))} -> 54 | P16: {=IFERROR(O16/G16*100,0)} -> 1.4705882 | Q16: {=INDEX('[20]LS (Deteksi) Agustus'!Q$7:Q$303,MATCH(1,('[20]LS (Deteksi) Agustus'!$D$7:$D$303=$D16)*('[20]LS (Deteksi) Agustus'!$D$7:$D$303=$D16),0))} -> 3 | R16: =IFERROR(Q16/O16*100,0) -> 5.5555556 | S16: {=IF(R16>5,"Perlu Sensus",IF(AND(R16>=0,O16>0),"Tetap Deteksi","Belum Deteksi"))} -> Perlu Sensus | T16: {=INDEX('[20]LS (Deteksi) Agustus'!T$7:T$303,MATCH(1,('[20]LS (Deteksi) Agustus'!$D$7:$D$303=$D16)*('[20]LS (Deteksi) Agustus'!$D$7:$D$303=$D16),0))} -> 14 | U16: =IFERROR(T16/O16*100,0) -> 25.925926 | V16: {=INDEX('[20]LS (Deteksi) Agustus'!V$7:V$303,MATCH(1,('[20]LS (Deteksi) Agustus'!$D$7:$D$303=$D16)*('[20]LS (Deteksi) Agustus'!$D$7:$D$303=$D16),0))} -> 46242 | W16: {=INDEX('[20]LS (Deteksi) Agustus'!W$7:W$303,MATCH(1,('[20]LS (Deteksi) Agustus'!$D$7:$D$303=$D16)*('[20]LS (Deteksi) Agustus'!$D$7:$D$303=$D16),0))} -> 233 | X16: {=INDEX('[20]LS (Deteksi) Agustus'!X$7:X$303,MATCH(1,('[20]LS (Deteksi) Agustus'!$D$7:$D$303=$D16)*('[20]LS (Deteksi) Agustus'!$D$7:$D$303=$D16),0))} -> 15 | Y16: =IFERROR(X16/W16*100,0) -> 6.4377682 | Z16: {=IF(Y16>5,"Perlu Sensus",IF(AND(Y16>0,,O16>0),"Tetap Deteksi","Belum Deteksi"))} -> Perlu Sensus | AA16: {=INDEX('[20]LS (Deteksi) Agustus'!AA$7:AA$303,MATCH(1,('[20]LS (Deteksi) Agustus'!$D$7:$D$303=$D16)*('[20]LS (Deteksi) Agustus'!$D$7:$D$303=$D16),0))} -> 15 | AB16: =IFERROR(AA16/W16*100,0) -> 6.4377682
A17: LS I | B17: I | C17: I | D17: B16 | E17: 24.21 | F17: GAMBUT | G17: 3591 | H17: =IF(N17>0,N17,V17) -> 46241 | I17: =IF(O17>0,O17,W17) -> 120 | J17: =IF(P17>0,P17," ") -> 3.3416876 | K17: =IF(Q17>0,Q17,X17) -> 11 | L17: =IFERROR(K17/I17*100,0) -> 9.1666667 | M17: {=IF(L17>5,"Perlu Sensus",IF(AND(L17>=0,I17>0),"Tetap Deteksi","Belum Deteksi"))} -> Perlu Sensus | N17: {=INDEX('[20]LS (Deteksi) Agustus'!N$7:N$303,MATCH(1,('[20]LS (Deteksi) Agustus'!$D$7:$D$303=$D17)*('[20]LS (Deteksi) Agustus'!$D$7:$D$303=$D17),0))} -> 46241 | O17: {=INDEX('[20]LS (Deteksi) Agustus'!O$7:O$303,MATCH(1,('[20]LS (Deteksi) Agustus'!$D$7:$D$303=$D17)*('[20]LS (Deteksi) Agustus'!$D$7:$D$303=$D17),0))} -> 120 | P17: {=IFERROR(O17/G17*100,0)} -> 3.3416876 | Q17: {=INDEX('[20]LS (Deteksi) Agustus'!Q$7:Q$303,MATCH(1,('[20]LS (Deteksi) Agustus'!$D$7:$D$303=$D17)*('[20]LS (Deteksi) Agustus'!$D$7:$D$303=$D17),0))} -> 11 | R17: =IFERROR(Q17/O17*100,0) -> 9.1666667 | S17: {=IF(R17>5,"Perlu Sensus",IF(AND(R17>=0,O17>0),"Tetap Deteksi","Belum Deteksi"))} -> Perlu Sensus | T17: {=INDEX('[20]LS (Deteksi) Agustus'!T$7:T$303,MATCH(1,('[20]LS (Deteksi) Agustus'!$D$7:$D$303=$D17)*('[20]LS (Deteksi) Agustus'!$D$7:$D$303=$D17),0))} -> 15 | U17: =IFERROR(T17/O17*100,0) -> 12.5 | V17: {=INDEX('[20]LS (Deteksi) Agustus'!V$7:V$303,MATCH(1,('[20]LS (Deteksi) Agustus'!$D$7:$D$303=$D17)*('[20]LS (Deteksi) Agustus'!$D$7:$D$303=$D17),0))} -> 46242 | W17: {=INDEX('[20]LS (Deteksi) Agustus'!W$7:W$303,MATCH(1,('[20]LS (Deteksi) Agustus'!$D$7:$D$303=$D17)*('[20]LS (Deteksi) Agustus'!$D$7:$D$303=$D17),0))} -> 298 | X17: {=INDEX('[20]LS (Deteksi) Agustus'!X$7:X$303,MATCH(1,('[20]LS (Deteksi) Agustus'!$D$7:$D$303=$D17)*('[20]LS (Deteksi) Agustus'!$D$7:$D$303=$D17),0))} -> 20 | Y17: =IFERROR(X17/W17*100,0) -> 6.7114094 | Z17: {=IF(Y17>5,"Perlu Sensus",IF(AND(Y17>0,,O17>0),"Tetap Deteksi","Belum Deteksi"))} -> Perlu Sensus | AA17: {=INDEX('[20]LS (Deteksi) Agustus'!AA$7:AA$303,MATCH(1,('[20]LS (Deteksi) Agustus'!$D$7:$D$303=$D17)*('[20]LS (Deteksi) Agustus'!$D$7:$D$303=$D17),0))} -> 25 | AB17: =IFERROR(AA17/W17*100,0) -> 8.3892617
... A157: LS I | B157: I | C157: V | D157: K16 | E157: 45.08 | F157: PASIR | G157: 6402 | H157: =IF(N157>0,N157,V157) -> 46235 | I157: =IF(O157>0,O157,W157) -> 58 | J157: =IF(P157>0,P157," ") -> 0.90596689 | K157: =IF(Q157>0,Q157,X157) -> 2 | L157: =IFERROR(K157/I157*100,0) -> 3.4482759 | M157: {=IF(L157>5,"Perlu Sensus",IF(AND(L157>=0,I157>0),"Tetap Deteksi","Belum Deteksi"))} -> Tetap Deteksi | N157: {=INDEX('[20]LS (Deteksi) Agustus'!N$7:N$303,MATCH(1,('[20]LS (Deteksi) Agustus'!$D$7:$D$303=$D157)*('[20]LS (Deteksi) Agustus'!$D$7:$D$303=$D157),0))} -> 46235 | O157: {=INDEX('[20]LS (Deteksi) Agustus'!O$7:O$303,MATCH(1,('[20]LS (Deteksi) Agustus'!$D$7:$D$303=$D157)*('[20]LS (Deteksi) Agustus'!$D$7:$D$303=$D157),0))} -> 58 | P157: {=IFERROR(O157/G157*100,0)} -> 0.90596689 | Q157: {=INDEX('[20]LS (Deteksi) Agustus'!Q$7:Q$303,MATCH(1,('[20]LS (Deteksi) Agustus'!$D$7:$D$303=$D157)*('[20]LS (Deteksi) Agustus'!$D$7:$D$303=$D157),0))} -> 2 | R157: =IFERROR(Q157/O157*100,0) -> 3.4482759 | S157: {=IF(R157>5,"Perlu Sensus",IF(AND(R157>=0,O157>0),"Tetap Deteksi","Belum Deteksi"))} -> Tetap Deteksi | T157: {=INDEX('[20]LS (Deteksi) Agustus'!T$7:T$303,MATCH(1,('[20]LS (Deteksi) Agustus'!$D$7:$D$303=$D157)*('[20]LS (Deteksi) Agustus'!$D$7:$D$303=$D157),0))} -> 45 | U157: =IFERROR(T157/O157*100,0) -> 77.586207 | V157: {=INDEX('[20]LS (Deteksi) Agustus'!V$7:V$303,MATCH(1,('[20]LS (Deteksi) Agustus'!$D$7:$D$303=$D157)*('[20]LS (Deteksi) Agustus'!$D$7:$D$303=$D157),0))} -> 0 | W157: {=INDEX('[20]LS (Deteksi) Agustus'!W$7:W$303,MATCH(1,('[20]LS (Deteksi) Agustus'!$D$7:$D$303=$D157)*('[20]LS (Deteksi) Agustus'!$D$7:$D$303=$D157),0))} -> 0 | X157: {=INDEX('[20]LS (Deteksi) Agustus'!X$7:X$303,MATCH(1,('[20]LS (Deteksi) Agustus'!$D$7:$D$303=$D157)*('[20]LS (Deteksi) Agustus'!$D$7:$D$303=$D157),0))} -> 0 | Y157: =IFERROR(X157/W157*100,0) -> 0 | Z157: {=IF(Y157>5,"Perlu Sensus",IF(AND(Y157>0,,O157>0),"Tetap Deteksi","Belum Deteksi"))} -> Belum Deteksi | AA157: {=INDEX('[20]LS (Deteksi) Agustus'!AA$7:AA$303,MATCH(1,('[20]LS (Deteksi) Agustus'!$D$7:$D$303=$D157)*('[20]LS (Deteksi) Agustus'!$D$7:$D$303=$D157),0))} -> 0 | AB157: =IFERROR(AA157/W157*100,0) -> 0
A158: LS I | B158: II | C158: VI | D158: L10 | E158: 33.32 | F158: PASIR | G158: 4628 | H158: =IF(N158>0,N158,V158) -> 46242 | I158: =IF(O158>0,O158,W158) -> 136 | J158: =IF(P158>0,P158," ") -> 2.9386344 | K158: =IF(Q158>0,Q158,X158) -> 8 | L158: =IFERROR(K158/I158*100,0) -> 5.8823529 | M158: {=IF(L158>5,"Perlu Sensus",IF(AND(L158>=0,I158>0),"Tetap Deteksi","Belum Deteksi"))} -> Perlu Sensus | N158: 46242 | O158: 136 | P158: {=IFERROR(O158/G158*100,0)} -> 2.9386344 | Q158: 8 | R158: =IFERROR(Q158/O158*100,0) -> 5.8823529 | S158: {=IF(R158>5,"Perlu Sensus",IF(AND(R158>=0,O158>0),"Tetap Deteksi","Belum Deteksi"))} -> Perlu Sensus | T158: {=INDEX('[20]LS (Deteksi) Agustus'!T$7:T$303,MATCH(1,('[20]LS (Deteksi) Agustus'!$D$7:$D$303=$D158)*('[20]LS (Deteksi) Agustus'!$D$7:$D$303=$D158),0))} -> 0 | U158: =IFERROR(T158/O158*100,0) -> 0 | V158: 46244 | W158: 203 | X158: 8 | Y158: =IFERROR(X158/W158*100,0) -> 3.9408867 | Z158: {=IF(Y158>5,"Perlu Sensus",IF(AND(Y158>0,,O158>0),"Tetap Deteksi","Belum Deteksi"))} -> Belum Deteksi | AA158: {=INDEX('[20]LS (Deteksi) Agustus'!AA$7:AA$303,MATCH(1,('[20]LS (Deteksi) Agustus'!$D$7:$D$303=$D158)*('[20]LS (Deteksi) Agustus'!$D$7:$D$303=$D158),0))} -> 0 | AB158: =IFERROR(AA158/W158*100,0) -> 0
A159: LS I | B159: II | C159: VI | D159: L11 | E159: 25.36 | F159: PASIR | G159: 3827 | H159: =IF(N159>0,N159,V159) -> 46242 | I159: =IF(O159>0,O159,W159) -> 118 | J159: =IF(P159>0,P159," ") -> 3.0833551 | K159: =IF(Q159>0,Q159,X159) -> 6 | L159: =IFERROR(K159/I159*100,0) -> 5.0847458 | M159: {=IF(L159>5,"Perlu Sensus",IF(AND(L159>=0,I159>0),"Tetap Deteksi","Belum Deteksi"))} -> Perlu Sensus | N159: 46242 | O159: 118 | P159: {=IFERROR(O159/G159*100,0)} -> 3.0833551 | Q159: 6 | R159: =IFERROR(Q159/O159*100,0) -> 5.0847458 | S159: {=IF(R159>5,"Perlu Sensus",IF(AND(R159>=0,O159>0),"Tetap Deteksi","Belum Deteksi"))} -> Perlu Sensus | T159: {=INDEX('[20]LS (Deteksi) Agustus'!T$7:T$303,MATCH(1,('[20]LS (Deteksi) Agustus'!$D$7:$D$303=$D159)*('[20]LS (Deteksi) Agustus'!$D$7:$D$303=$D159),0))} -> 0 | U159: =IFERROR(T159/O159*100,0) -> 0 | V159: 46244 | W159: 223 | X159: 9 | Y159: =IFERROR(X159/W159*100,0) -> 4.0358744 | Z159: {=IF(Y159>5,"Perlu Sensus",IF(AND(Y159>0,,O159>0),"Tetap Deteksi","Belum Deteksi"))} -> Belum Deteksi | AA159: {=INDEX('[20]LS (Deteksi) Agustus'!AA$7:AA$303,MATCH(1,('[20]LS (Deteksi) Agustus'!$D$7:$D$303=$D159)*('[20]LS (Deteksi) Agustus'!$D$7:$D$303=$D159),0))} -> 0 | AB159: =IFERROR(AA159/W159*100,0) -> 0
A160: LS I | B160: II | C160: VI | D160: L12 | E160: 25.06 | F160: PASIR | G160: 3856 | H160: =IF(N160>0,N160,V160) -> 46242 | I160: =IF(O160>0,O160,W160) -> 119 | J160: =IF(P160>0,P160," ") -> 3.0860996 | K160: =IF(Q160>0,Q160,X160) -> 21 | L160: =IFERROR(K160/I160*100,0) -> 17.647059 | M160: {=IF(L160>5,"Perlu Sensus",IF(AND(L160>=0,I160>0),"Tetap Deteksi","Belum Deteksi"))} -> Perlu Sensus | N160: 46242 | O160: 119 | P160: {=IFERROR(O160/G160*100,0)} -> 3.0860996 | Q160: 21 | R160: =IFERROR(Q160/O160*100,0) -> 17.647059 | S160: {=IF(R160>5,"Perlu Sensus",IF(AND(R160>=0,O160>0),"Tetap Deteksi","Belum Deteksi"))} -> Perlu Sensus | T160: {=INDEX('[20]LS (Deteksi) Agustus'!T$7:T$303,MATCH(1,('[20]LS (Deteksi) Agustus'!$D$7:$D$303=$D160)*('[20]LS (Deteksi) Agustus'!$D$7:$D$303=$D160),0))} -> 0 | U160: =IFERROR(T160/O160*100,0) -> 0 | V160: 46244 | W160: 215 | X160: 20 | Y160: =IFERROR(X160/W160*100,0) -> 9.3023256 | Z160: {=IF(Y160>5,"Perlu Sensus",IF(AND(Y160>0,,O160>0),"Tetap Deteksi","Belum Deteksi"))} -> Perlu Sensus | AA160: {=INDEX('[20]LS (Deteksi) Agustus'!AA$7:AA$303,MATCH(1,('[20]LS (Deteksi) Agustus'!$D$7:$D$303=$D160)*('[20]LS (Deteksi) Agustus'!$D$7:$D$303=$D160),0))} -> 0 | AB160: =IFERROR(AA160/W160*100,0) -> 0
A161: LS I | B161: II | C161: VI | D161: L13 | E161: 24.9 | F161: PASIR | G161: 3638 | H161: =IF(N161>0,N161,V161) -> 46248 | I161: =IF(O161>0,O161,W161) -> 222 | J161: =IF(P161>0,P161," ") -> 6.102254 | K161: =IF(Q161>0,Q161,X161) -> 2 | L161: =IFERROR(K161/I161*100,0) -> 0.9009009 | M161: {=IF(L161>5,"Perlu Sensus",IF(AND(L161>=0,I161>0),"Tetap Deteksi","Belum Deteksi"))} -> Tetap Deteksi | N161: 46248 | O161: 222 | P161: {=IFERROR(O161/G161*100,0)} -> 6.102254 | Q161: 2 | R161: =IFERROR(Q161/O161*100,0) -> 0.9009009 | S161: {=IF(R161>5,"Perlu Sensus",IF(AND(R161>=0,O161>0),"Tetap Deteksi","Belum Deteksi"))} -> Tetap Deteksi | T161: {=INDEX('[20]LS (Deteksi) Agustus'!T$7:T$303,MATCH(1,('[20]LS (Deteksi) Agustus'!$D$7:$D$303=$D161)*('[20]LS (Deteksi) Agustus'!$D$7:$D$303=$D161),0))} -> 0 | U161: =IFERROR(T161/O161*100,0) -> 0 | V161: 46249 | W161: 48 | X161: 1 | Y161: =IFERROR(X161/W161*100,0) -> 2.0833333 | Z161: {=IF(Y161>5,"Perlu Sensus",IF(AND(Y161>0,,O161>0),"Tetap Deteksi","Belum Deteksi"))} -> Belum Deteksi | AA161: {=INDEX('[20]LS (Deteksi) Agustus'!AA$7:AA$303,MATCH(1,('[20]LS (Deteksi) Agustus'!$D$7:$D$303=$D161)*('[20]LS (Deteksi) Agustus'!$D$7:$D$303=$D161),0))} -> 0 | AB161: =IFERROR(AA161/W161*100,0) -> 0
A162: LS I | B162: II | C162: VI | D162: L14 | E162: 25.35 | F162: PASIR | G162: 3683 | H162: =IF(N162>0,N162,V162) -> 46244 | I162: =IF(O162>0,O162,W162) -> 112 | J162: =IF(P162>0,P162," ") -> 3.0409992 | K162: =IF(Q162>0,Q162,X162) -> 6 | L162: =IFERROR(K162/I162*100,0) -> 5.3571429 | M162: {=IF(L162>5,"Perlu Sensus",IF(AND(L162>=0,I162>0),"Tetap Deteksi","Belum Deteksi"))} -> Perlu Sensus | N162: 46244 | O162: 112 | P162: {=IFERROR(O162/G162*100,0)} -> 3.0409992 | Q162: 6 | R162: =IFERROR(Q162/O162*100,0) -> 5.3571429 | S162: {=IF(R162>5,"Perlu Sensus",IF(AND(R162>=0,O162>0),"Tetap Deteksi","Belum Deteksi"))} -> Perlu Sensus | T162: {=INDEX('[20]LS (Deteksi) Agustus'!T$7:T$303,MATCH(1,('[20]LS (Deteksi) Agustus'!$D$7:$D$303=$D162)*('[20]LS (Deteksi) Agustus'!$D$7:$D$303=$D162),0))} -> 0 | U162: =IFERROR(T162/O162*100,0) -> 0 | V162: 46245 | W162: 289 | X162: 5 | Y162: =IFERROR(X162/W162*100,0) -> 1.7301038 | Z162: {=IF(Y162>5,"Perlu Sensus",IF(AND(Y162>0,,O162>0),"Tetap Deteksi","Belum Deteksi"))} -> Belum Deteksi | AA162: {=INDEX('[20]LS (Deteksi) Agustus'!AA$7:AA$303,MATCH(1,('[20]LS (Deteksi) Agustus'!$D$7:$D$303=$D162)*('[20]LS (Deteksi) Agustus'!$D$7:$D$303=$D162),0))} -> 0 | AB162: =IFERROR(AA162/W162*100,0) -> 0
A163: LS I | B163: II | C163: VI | D163: L15 | E163: 24.52 | F163: PASIR | G163: 3584 | H163: =IF(N163>0,N163,V163) -> 46248 | I163: =IF(O163>0,O163,W163) -> 147 | J163: =IF(P163>0,P163," ") -> 4.1015625 | K163: =IF(Q163>0,Q163,X163) -> 4 | L163: =IFERROR(K163/I163*100,0) -> 2.7210884 | M163: {=IF(L163>5,"Perlu Sensus",IF(AND(L163>=0,I163>0),"Tetap Deteksi","Belum Deteksi"))} -> Tetap Deteksi | N163: 46248 | O163: 147 | P163: {=IFERROR(O163/G163*100,0)} -> 4.1015625 | Q163: 4 | R163: =IFERROR(Q163/O163*100,0) -> 2.7210884 | S163: {=IF(R163>5,"Perlu Sensus",IF(AND(R163>=0,O163>0),"Tetap Deteksi","Belum Deteksi"))} -> Tetap Deteksi | T163: {=INDEX('[20]LS (Deteksi) Agustus'!T$7:T$303,MATCH(1,('[20]LS (Deteksi) Agustus'!$D$7:$D$303=$D163)*('[20]LS (Deteksi) Agustus'!$D$7:$D$303=$D163),0))} -> 0 | U163: =IFERROR(T163/O163*100,0) -> 0 | V163: 46246 | W163: 260 | X163: 3 | Y163: =IFERROR(X163/W163*100,0) -> 1.1538462 | Z163: {=IF(Y163>5,"Perlu Sensus",IF(AND(Y163>0,,O163>0),"Tetap Deteksi","Belum Deteksi"))} -> Belum Deteksi | AA163: {=INDEX('[20]LS (Deteksi) Agustus'!AA$7:AA$303,MATCH(1,('[20]LS (Deteksi) Agustus'!$D$7:$D$303=$D163)*('[20]LS (Deteksi) Agustus'!$D$7:$D$303=$D163),0))} -> 0 | AB163: =IFERROR(AA163/W163*100,0) -> 0
A164: LS I | B164: II | C164: VI | D164: L16 | E164: 24.59 | F164: PASIR | G164: 3638 | H164: =IF(N164>0,N164,V164) -> 46248 | I164: =IF(O164>0,O164,W164) -> 147 | J164: =IF(P164>0,P164," ") -> 4.0406817 | K164: =IF(Q164>0,Q164,X164) -> 2 | L164: =IFERROR(K164/I164*100,0) -> 1.3605442 | M164: {=IF(L164>5,"Perlu Sensus",IF(AND(L164>=0,I164>0),"Tetap Deteksi","Belum Deteksi"))} -> Tetap Deteksi | N164: 46248 | O164: 147 | P164: {=IFERROR(O164/G164*100,0)} -> 4.0406817 | Q164: 2 | R164: =IFERROR(Q164/O164*100,0) -> 1.3605442 | S164: {=IF(R164>5,"Perlu Sensus",IF(AND(R164>=0,O164>0),"Tetap Deteksi","Belum Deteksi"))} -> Tetap Deteksi | T164: {=INDEX('[20]LS (Deteksi) Agustus'!T$7:T$303,MATCH(1,('[20]LS (Deteksi) Agustus'!$D$7:$D$303=$D164)*('[20]LS (Deteksi) Agustus'!$D$7:$D$303=$D164),0))} -> 0 | U164: =IFERROR(T164/O164*100,0) -> 0 | V164: 46249 | W164: 48 | X164: 2 | Y164: =IFERROR(X164/W164*100,0) -> 4.1666667 | Z164: {=IF(Y164>5,"Perlu Sensus",IF(AND(Y164>0,,O164>0),"Tetap Deteksi","Belum Deteksi"))} -> Belum Deteksi | AA164: {=INDEX('[20]LS (Deteksi) Agustus'!AA$7:AA$303,MATCH(1,('[20]LS (Deteksi) Agustus'!$D$7:$D$303=$D164)*('[20]LS (Deteksi) Agustus'!$D$7:$D$303=$D164),0))} -> 0 | AB164: =IFERROR(AA164/W164*100,0) -> 0
