Workbook
Name G: #N/A
Name D: #N/A
Name _\0: #REF!
Name _\a: #REF!
Name _\b: #N/A
Name _\c: #N/A
Name _\d: #N/A
Name _\e: #N/A
Name _\f: #N/A
Name _\g: #N/A
Name _\h: #N/A
Name _\HT01: [1]材料汇总表!$G$33:$G$62
Name _\HT02: [1]材料汇总表!$J$33:$J$62
Name _\i: #N/A
Name _\j: #N/A
Name _\k: #N/A
Name _\l: #N/A
Name _\m: #N/A
Name _\n: #N/A
Name _\NW01: [1]材料汇总表!$H$33:$H$62
Name _\NW02: [1]材料汇总表!$K$33:$K$62
Name _\o: #N/A
Name _\p: #N/A
Name _\q: #N/A
Name _\s: #N/A
Name _\VSF01: [1]材料汇总表!$F$33:$F$62
Name _\VSF02: [1]材料汇总表!$I$33:$I$62
Name _\w: #N/A
Name _\y: #N/A
Name _\z: #N/A
Name ______\0: #REF!
Name ______\a: #REF!
Name _____MA0303: #N/A
Name _____MA0304: #N/A
Name ____MA0303: #N/A
Name ____MA0304: #N/A
Name ___MA0303: #N/A
Name ___MA0304: #N/A
Name __MA0303: #N/A
Name __MA0304: #N/A
Name _02: #N/A
Name _09: #N/A
Name _10: #N/A
Name _14: #N/A
Name _432: 432
Name _b: #N/A
Name _g: #N/A
Name _HOME___PG_FRSE: #N/A
Name _MA0303: #N/A
Name _MA0304: #N/A
Name _n: #N/A
Name _Regression_Int: 1
Name A___13: #N/A
Name AGT: #N/A
Name ANTO: #N/A
Name APR: #N/A
Name B: #N/A
Name Book1: #N/A
Name C_: #N/A
Name CAP_1: #N/A

Sheet DATA LOKASI PINTU AIR
C1: PT. SURYA INTISARI RAYA - 1 | K1: 10
C2: KEBUN SEI LUKUT
C3: FR GROUP
B5: DATA INVENTARIS PINTU AIR KEBUN SIR LUKUT 2026
B8: ='TGL ROUDMAP PENGECEKAN'!B8 -> BULAN | C8: UPDATE 18 AGUSTUS 2026
B9: AFD | C9: BLOK | D9: TITIK KOORDINAT | E9: NOMOR PINTU AIR | F9: JEIS PINTU AIR KEBUTUHAN POKOK (UNIT) | I9: KONDISI PINTU AIR | K9: KETERANGAN
F10: HDPE | G10: WATERGATE | H10: DRUM GATE | I10: KONDISI PINTU AIR
B11: I | C11: A22 | D11: 0.629334,101.511331 | E11: WG01 | G11: √ | I11: BAIK
C12: B22 | D12: 0.629104,101.520619 | E12: WG02 | G12: √ | J12: RUSAK | K12: ENSEL PINTU LEPAS
C13: B21 | D13: 0.626629,101.525939 | E13: WG03 | G13: √ | J13: RUSAK | K13: PINTU HILANG
C14: B21 | D14: 0.628887,101.523902 | E14: WG04 | G14: √ | I14: BAIK
C15: B20 | D15: 0.626360,101.526088 | E15: DG01 | H15: √ | J15: RUSAK | K15: PINTU HILANG
C16: C21 | D16: 0.626750,101.526514 | E16: WG05 | G16: √ | I16: BAIK
C17: C20 | D17: 0.624308,101.529971 | E17: WG06 | G17: √ | I17: BAIK
C18: C20 | D18: 0.624386,101.528289 | E18: DG02 | H18: √ | I18: BAIK
C19: C17 | D19: 0.617466,101.533407 | E19: DG03 | H19: √ | I19: BAIK
C20: C15 | D20: 0,612845,101.533407 | E20: DG04 | H20: √ | I20: BAIK
C21: C14 | D21: 0.612559,101.533281 | E21: DG05 | H21: √ | J21: RUSAK | K21: PINTU HILANG
C22: C11 | D22: 0.603865,101.533889 | E22: WG07 | G22: √ | I22: BAIK
C23: C10 | D23: 0.603510,101.533925 | E23: WG08 | G23: √ | J23: RUSAK | K23: ENSEL PINTU LEPAS
C24: D7 | D24: 0.594732,101.540468 | E24: WG09 | G24: √ | I24: BAIK
C25: D5 | D25: 0.590353,101.543947 | E25: WG10 | G25: √ | I25: BAIK
B26: TOTAL | G26: 10 | H26: 5
B27: II | C27: D10 | D27: 0036.210;101032.077' | E27: WG11 | G27: √ | I27: BAIK
C28: F25 | D28: 0038.173;101033.405' | E28: WG12 | G28: √ | I28: BAIK
C29: F25 | D29: 0038.233;101033.652' | E29: DG06 | H29: √ | I29: BAIK
B30: TOTAL | D30: 0 | G30: 2 | H30: 1
B31: III | C31: G19 | D31: 0.622685, 101.567482 | E31: DG06 | H31: √ | I31: BAIK
C32: G19 | D32: 0.622820, 101.570032 | E32: HDPE01 | F32: √ | I32: BAIK
C33: H20 | D33: 0.627122, 101.572180 | E33: DG07 | H33: √ | I33: BAIK
C34: H21 | D34: 0.627753, 101.572740 | E34: DG08 | H34: √ | I34: BAIK
C35: H23 | D35: 0.631985, 101.573525 | E35: DG09 | H35: √ | I35: BAIK
C36: H23 | D36: 0.631992, 101.573635 | E36: HDPE02 | F36: √ | I36: BAIK
C37: I20 | D37: 0.625707, 101.588142 | E37: HDPE03 | F37: √ | I37: BAIK
C38: I22 | D38: 0.631910, 101.584373 | E38: DG10 | H38: √ | I38: BAIK
C39: I23 | D39: 0.632093, 101.584567 | E39: DG11 | H39: √ | I39: BAIK
C40: I23 | D40: 0.632198, 101.584383 | E40: DG12 | H40: √ | I40: BAIK
C41: I25 | D41: 0.638847, 101.584553 | E41: DG13 | H41: √ | I41: BAIK
C42: J18 | D42: 0.620511, 101.592068 | E42: WG13 | G42: √ | J42: RUSAK | K42: PINTU HILANG
C43: J18 | D43: 0.622977, 101.589528 | E43: WG14 | G43: √ | I43: BAIK
...

Sheet TGL ROUDMAP PENGECEKAN
C1: PT. SURYA INTISARI RAYA - 1 | G1: 10
C2: KEBUN SEI LUKUT
C3: FR GROUP
B5: DATA ROUDMAP PENGECEKAN TANGGAL PINTU AIR KEBUN SIR LUKUT 2026
B8: BULAN | C8: 46239
B9: AFD | C9: BLOK | D9: TITIK KOORDINAT | E9: NOMOR PINTU AIR | F9: JEIS PINTU AIR | G9: TANGGAL PENGECEKAN
G10: 1 | H10: 2 | I10: 3 | J10: 4 | K10: 5 | L10: 6 | M10: 7 | N10: 8 | O10: 9 | P10: 10 | Q10: 11 | R10: 12 | S10: 13 | T10: 14 | U10: 15 | V10: 16 | W10: 17 | X10: 18 | Y10: 19 | Z10: 20 | AA10: 21 | AB10: 22 | AC10: 23 | AD10: 24 | AE10: 25 | AF10: 26 | AG10: 27 | AH10: 28 | AI10: 29 | AJ10: 30 | AK10: 31
B11: I | C11: A22 | D11: 0.629334,101.511331 | E11: WG01 | F11: WATERGATE
C12: B22 | D12: 0.629104,101.520619 | E12: WG02 | F12: WATERGATE
C13: B21 | D13: 0.626629,101.525939 | E13: WG03 | F13: WATERGATE
C14: B21 | D14: 0.628887,101.523902 | E14: WG04 | F14: WATERGATE
C15: B20 | D15: 0.626360,101.526088 | E15: DG01 | F15: DRUMGATE
C16: C21 | D16: 0.626750,101.526514 | E16: WG05 | F16: WATERGATE
C17: C20 | D17: 0.624308,101.529971 | E17: WG06 | F17: WATERGATE
C18: C20 | D18: 0.624386,101.528289 | E18: DG02 | F18: DRUMGATE
C19: C17 | D19: 0.617466,101.533407 | E19: DG03 | F19: DRUMGATE
C20: C15 | D20: 0,612845,101.533407 | E20: DG04 | F20: DRUMGATE
C21: C14 | D21: 0.612559,101.533281 | E21: DG05 | F21: DRUMGATE
C22: C11 | D22: 0.603865,101.533889 | E22: WG07 | F22: WATERGATE
C23: C10 | D23: 0.603510,101.533925 | E23: WG08 | F23: WATERGATE
... C25: D5 | D25: 0.590353,101.543947 | E25: WG10 | F25: WATERGATE
B26: TOTAL
B27: II | C27: D10 | D27: 0036.210;101032.077' | E27: WG11 | F27: WATERGATE
C28: F25 | D28: 0038.173;101033.405' | E28: WG12 | F28: WATERGATE
C29: F25 | D29: 0038.233;101033.652' | E29: DG06 | F29: DRUMGATE
B30: TOTAL | D30: =SUM(D27:D29) -> 0
B31: III | C31: G19 | D31: ='DATA LOKASI PINTU AIR'!D31 -> 0.622685, 101.567482 | E31: DG06 | F31: DRUMGATE
C32: G19 | D32: ='DATA LOKASI PINTU AIR'!D32 -> 0.622820, 101.570032 | E32: HDPE01 | F32: HDPE
C33: H20 | D33: ='DATA LOKASI PINTU AIR'!D33 -> 0.627122, 101.572180 | E33: DG07 | F33: DRUMGATE
C34: H21 | D34: ='DATA LOKASI PINTU AIR'!D34 -> 0.627753, 101.572740 | E34: DG08 | F34: DRUMGATE
C35: H23 | D35: ='DATA LOKASI PINTU AIR'!D35 -> 0.631985, 101.573525 | E35: DG09 | F35: DRUMGATE
C36: H23 | D36: ='DATA LOKASI PINTU AIR'!D36 -> 0.631992, 101.573635 | E36: HDPE02 | F36: HDPE
C37: I20 | D37: ='DATA LOKASI PINTU AIR'!D37 -> 0.625707, 101.588142 | E37: HDPE03 | F37: HDPE
C38: I22 | D38: ='DATA LOKASI PINTU AIR'!D38 -> 0.631910, 101.584373 | E38: DG10 | F38: DRUMGATE
C39: I23 | D39: ='DATA LOKASI PINTU AIR'!D39 -> 0.632093, 101.584567 | E39: DG11 | F39: DRUMGATE
C40: I23 | D40: ='DATA LOKASI PINTU AIR'!D40 -> 0.632198, 101.584383 | E40: DG12 | F40: DRUMGATE
C41: I25 | D41: ='DATA LOKASI PINTU AIR'!D41 -> 0.638847, 101.584553 | E41: DG13 | F41: DRUMGATE
C42: J18 | D42: ='DATA LOKASI PINTU AIR'!D42 -> 0.620511, 101.592068 | E42: WG13 | F42: WATERGATE
C43: J18 | D43: ='DATA LOKASI PINTU AIR'!D43 -> 0.622977, 101.589528 | E43: WG14 | F43: WATERGATE
... C46: J20 | D46: ='DATA LOKASI PINTU AIR'!D46 -> 0.625690, 101.596447 | E46: HDPE04 | F46: √
...

Sheet PETA PINTU AIR
G3: AA | H3: A | J3: B | L3: C | N3: D | P3: E | R3: F | T3: G | V3: H | X3: I | Z3: J
B8: 31 | X8: I31 | Y8: I31 | Z8: J31 | AA8: J31
B9: 30 | V9: H30 | W9: H30 | X9: I30 | Y9: I30 | Z9: J30 | AA9: J30
B10: 29 | T10: G29 | U10: G29 | V10: H29 | W10: H29 | X10: I29 | Y10: I29 | Z10: J29 | AA10: J29
B11: 28 | S11: F28 | T11: G28 | U11: G28 | V11: H28 | W11: H28 | X11: I28 | Y11: I28 | Z11: J28 | AA11: J28
B12: 27 | J12: B27 | K12: B27 | L12: B27 | R12: F27 | S12: F27 | T12: G27 | U12: G27 | V12: H27 | W12: H27 | X12: I27 | Y12: I27 | Z12: J27 | AA12: J27
B13: 26 | J13: B26 | K13: B26 | L13: C26 | M13: C26 | P13: E26 | Q13: E26 | R13: F26 | S13: F26 | T13: G26 | U13: G26 | V13: H26 | W13: H26 | X13: I26 | Y13: I26 | Z13: J26 | AA13: J26
B14: 25 | J14: B25 | K14: B25 | L14: C25 | M14: C25 | N14: D25 | O14: D25 | P14: E25 | Q14: E25 | R14: F25 | S14: F25 | T14: G25 | U14: G25 | V14: H25 | W14: H25 | X14: I25 | Y14: I25 | Z14: J25 | AA14: J25
B15: 24 | G15: AA24 | H15: A24 | I15: A24 | J15: B24 | K15: B24 | L15: C24 | M15: C24 | N15: D24 | O15: D24 | P15: E24 | Q15: E24 | R15: F24 | S15: F24 | T15: G24 | U15: G24 | V15: H24 | W15: H24 | X15: I24 | Y15: I24 | Z15: J24 | AA15: J24
B16: 23 | G16: AA23 | H16: A23 | I16: A23 | J16: B23 | K16: B23 | L16: C23 | M16: C23 | N16: D23 | O16: D23 | P16: E23 | Q16: E23 | R16: F23 | S16: F23 | T16: G23 | U16: G23 | V16: H23 | W16: H23 | X16: I23 | Y16: I23 | Z16: J23 | AA16: J23
B17: 22 | H17: A22 | I17: A22 | J17: B22 | K17: B22 | L17: C22 | M17: C22 | N17: D22 | O17: D22 | P17: E22 | Q17: E22 | R17: F22 | S17: F22 | T17: G22 | U17: G22 | V17: H22 | W17: H22 | X17: I22 | Y17: I22 | Z17: J22 | AA17: J22
B18: 21 | H18: A21 | I18: A21 | J18: B21 | K18: B21 | L18: C21 | M18: C21 | N18: D21 | O18: D21 | P18: E21 | Q18: E21 | R18: F21 | S18: F21 | T18: G21 | U18: G21 | V18: H21 | W18: H21 | X18: I21 | Y18: I21 | Z18: J21 | AA18: J21
B19: 20 | H19: A20 | I19: A20 | J19: B20 | K19: B20 | L19: C20 | M19: C20 | N19: D20 | O19: D20 | P19: E20 | Q19: E20 | R19: F20 | S19: F20 | T19: G20 | U19: G20 | V19: H20 | W19: H20 | X19: I20 | Y19: I20 | Z19: J20 | AA19: J20
B20: 19 | H20: A19 | I20: A19 | J20: B19 | K20: B19 | L20: C19 | M20: C19 | N20: D19 | O20: D19 | P20: E19 | Q20: E19 | R20: F19 | S20: F19 | T20: G19 | U20: G19 | V20: H19 | W20: H19 | X20: I19 | Y20: I19 | Z20: J19 | AA20: J19
B21: 18 | H21: A18 | I21: A18 | J21: B18 | K21: B18 | L21: C18 | M21: C18 | N21: D18 | O21: D18 | P21: E18 | Q21: E18 | R21: F18 | S21: F18 | T21: G18 | U21: G18 | V21: H18 | W21: H18 | X21: I18 | Y21: I18 | Z21: J18 | AA21: J18
B22: 17 | H22: A17 | I22: A17 | J22: B17 | K22: B17 | L22: C17 | M22: C17 | N22: D17 | O22: D17 | P22: E17 | Q22: E17 | R22: F17 | S22: F17 | T22: G17 | U22: G17 | V22: H17 | W22: H17 | X22: I17 | Y22: I17 | Z22: J17 | AA22: J17
B23: 16 | J23: B16 | K23: B16 | L23: C16 | M23: C16 | N23: D16 | O23: D16 | P23: E16 | Q23: E16 | R23: F16 | S23: F16 | T23: G16 | U23: G16 | V23: H16 | W23: H16 | X23: I16 | Y23: I16 | Z23: J16 | AA23: J16
B24: 15 | J24: B15 | K24: B15 | L24: C15 | M24: C15 | N24: D15 | O24: D15 | P24: E15 | Q24: E15 | R24: F15 | S24: F15 | T24: G15 | U24: G15 | V24: H15 | W24: H15 | X24: I15 | Y24: I15 | Z24: J15 | AA24: J15
B25: 14 | J25: B14 | K25: B14 | L25: C14 | M25: C14 | N25: D14 | O25: D14 | P25: E14 | Q25: E14 | R25: F14 | S25: F14 | T25: G14 | U25: G14 | V25: H14 | W25: H14 | X25: I14 | Y25: I14 | Z25: J14 | AA25: J14
B26: 13 | J26: B13 | K26: B13 | L26: C13 | M26: C13 | N26: D13 | O26: D13 | P26: E13 | Q26: E13 | R26: F13 | S26: F13 | T26: G13 | U26: G13 | V26: H13 | W26: H13 | X26: I13 | Y26: I13 | Z26: J13 | AA26: J13
B27: 12 | J27: B12 | K27: B12 | L27: C12 | M27: C12 | N27: D12 | O27: D12 | P27: E12 | Q27: E12 | R27: F12 | S27: F12 | T27: G12 | U27: G12 | V27: H12 | W27: H12 | X27: I12 | Y27: I12 | Z27: J12 | AA27: J12
B28: 11 | L28: C11 | M28: C11 | N28: D11 | O28: D11 | P28: E11 | Q28: E11 | R28: F11 | S28: F11 | T28: G11 | U28: G11 | V28: H11 | W28: H11 | X28: I11 | Y28: I11 | Z28: J11 | AA28: J11
B29: 10 | L29: C10 | M29: C10 | N29: D10 | O29: D10 | P29: E10 | Q29: E10 | R29: F10 | S29: F10 | T29: G10 | U29: G10 | V29: H10 | W29: H10 | X29: I10 | Y29: I10 | Z29: J10
B30: 9 | L30: C9 | M30: C9 | N30: D9 | O30: D9 | P30: E9 | Q30: E9 | R30: F9 | S30: F9 | T30: G9 | U30: G9 | V30: H9 | W30: H9 | X30: I9 | Y30: I9
B31: 8 | L31: C8 | M31: C8 | N31: D8 | O31: D8 | P31: E8 | Q31: E8 | R31: F8 | S31: F8 | T31: G8 | U31: G8 | V31: H8 | W31: H8 | X31: I8 | Y31: I8
B32: 7 | N32: D7 | O32: D7 | P32: E7 | Q32: E7 | R32: F7 | S32: F7 | T32: G7 | U32: G7
B33: 6 | N33: D6 | O33: D6 | P33: E6 | Q33: E6 | R33: F6 | S33: F6 | T33: G6
B34: 5 | N34: D5 | O34: D5 | P34: E5 | Q34: E5 | R34: F5 | S34: F5 | T34: G5
B35: 4 | N35: D4 | O35: D4 | P35: E4 | Q35: E4 | R35: F4 | S35: F4
B36: 3 | N36: D3 | O36: D3 | P36: E3 | Q36: E3 | R36: F3 | S36: F3
B37: 2 | P37: E2 | Q37: E2 | R37: F2 | S37: F2
B38: 1 | P38: E1 | Q38: E1

Sheet TGL 16
C1: PT. SURYA INTISARI RAYA - 1
C2: KEBUN SEI LUKUT
C3: FR GROUP
B5: TANGGAL PENGECEKAN | E5: : 18 AGUSTUS 2026
B6: PETUGAS PENGECEKAN | E6: : WAWAN
E7: : DIMAS
B8: AFD | C8: BLOK | D8: JENIS PINTU AIR | E8: NOMOR PINTU AIR | F8: JENIS PENGAMATAN (PENGECEKAN)
F9: PEMBERSIHAN GRESS | G9: PEMBERSIHAN SAMPAH | H9: TINGGI AIR (CM) | I9: BAIK | J9: RUSAK
B10: I | C10: B22 | D10: WATER GATE | E10: WG02 | F10: √ | G10: √ | H10: 75 | J10: √
B11: I | C11: B21 | D11: WATER GATE | E11: WG03 | F11: √ | G11: √ | H11: 70 | I11: √
B12: I | C12: C21 | D12: WATER GATE | E12: WG05 | F12: √ | G12: √ | H12: 72 | I12: √
B13: I | C13: C20 | D13: WATER GATE | E13: WG06 | F13: √ | G13: √ | H13: 75 | I13: √
B14: I | C14: C22 | D14: DRUM GATE | E14: DG02 | F14: √ | G14: √ | H14: 75 | I14: √
B15: I | C15: B21 | D15: WATER GATE | E15: WG04 | F15: √ | G15: √ | H15: 70 | I15: √
B16: I | C16: C11 | D16: WATER GATE | E16: WG07 | F16: √ | G16: √ | H16: 80 | I16: √
B17: I | C17: C15 | D17: DRUM GATE | E17: DG604 | F17: √ | G17: √ | H17: 60 | I17: √
B18: I | C18: D7 | D18: WATER GATE | E18: WG09 | F18: √ | G18: √ | H18: 75 | J18: √
B19: I | C19: D5 | D19: WATER GATE | E19: WG10 | F19: √ | G19: √ | H19: 65 | I19: √
B20: I | C20: C17 | D20: DRUM GATE | E20: DG03 | F20: √ | G20: √ | H20: 60 | I20: √
B21: I | C21: C10 | D21: WATER GATE | E21: WG08 | F21: √ | G21: √ | H21: 70 | J21: √
B22: I | C22: A22 | D22: WATER GATE | E22: WG01 | F22: √ | G22: √ | H22: 65 | I22: √
B23: I | C23: C14 | D23: DRUM GATE | E23: D605 | F23: √ | G23: √ | H23: 60 | I23: √
B24: II | C24: F25 | D24: DRUM GATE | E24: D606 | F24: √ | G24: √ | H24: 70 | J24: √
B25: II | C25: F25 | D25: WATER GATE | E25: WG12 | F25: √ | G25: √ | H25: 45 | I25: √
B26: II | C26: D10 | D26: WATER GATE | E26: WG11 | F26: √ | G26: √ | H26: 60 | I26: √
B27: 3 | C27: H20 | D27: DRUM GATE | E27: DG07 | F27: √ | G27: √ | H27: 45 | I27: √
B28: 3 | C28: H21 | D28: DRUM GATE | E28: DG08 | F28: √ | G28: √ | H28: 45 | I28: √
B29: 3 | C29: G19 | D29: WATER GATE | E29: HDPE01 | F29: √ | G29: √ | H29: 60 | I29: √
B30: 3 | C30: G19 | D30: DRUM GATE | E30: DG06 | F30: √ | G30: √ | H30: 55 | I30: √

Sheet TGL 18
C1: PT. SURYA INTISARI RAYA - 1
C2: KEBUN SEI LUKUT
C3: FR GROUP
B5: TANGGAL PENGECEKAN | E5: : 5 AGUSTUS 2026
B6: PETUGAS PENGECEKAN | E6: : WAWAN
E7: : DIMAS
B8: AFD | C8: BLOK | D8: JENIS PINTU AIR | E8: NOMOR PINTU AIR | F8: JENIS PENGAMATAN (PENGECEKAN)
F9: PEMBERSIHAN GRESS | G9: PEMBERSIHAN SAMPAH | H9: TINGGI AIR (CM) | I9: BAIK | J9: RUSAK
B10: 3 | C10: J23 | D10: DRUM GATE | E10: DG11 | F10: √ | G10: √ | H10: 40 | J10: √
B11: 3 | C11: J19 | D11: DRUM GATE | E11: DG16 | F11: √ | G11: √ | H11: 45 | I11: √
B12: 3 | C12: J20 | D12: HDPE | E12: HDPE04 | F12: √ | G12: √ | H12: 50 | J12: √
B13: 3 | C13: H23 | D13: DRUM GATE | E13: DG09 | F13: √ | G13: √ | H13: 40 | I13: √
B14: 3 | C14: H23 | D14: HDPE | E14: HDPE02 | F14: √ | G14: √ | H14: 55 | I14: √
B15: 3 | C15: I20 | D15: HDPE | E15: HDPE03 | F15: √ | G15: √ | H15: 60 | I15: √
B16: 3 | C16: I22 | D16: DRUM GATE | E16: DG10 | F16: √ | G16: √ | H16: 45 | J16: √
B17: 3 | C17: I23 | D17: DRUM GATE | E17: DG11 | F17: √ | G17: √ | H17: 40 | I17: √
B18: 3 | C18: I23 | D18: DRUM GATE | E18: DG12 | F18: √ | G18: √ | H18: 60 | J18: √
B19: 3 | C19: J18 | D19: WATERGATE | E19: WG13 | F19: √ | G19: √ | H19: 50 | I19: √
B20: 3 | C20: J18 | D20: WATERGATE | E20: WG14 | F20: √ | G20: √ | H20: 35 | I20: √
B21: 3 | C21: J18 | D21: WATERGATE | E21: WG15 | F21: √ | G21: √ | H21: 40 | I21: √
B22: 4 | C22: J12 | D22: WATERGATE | E22: WG19 | F22: √ | G22: √ | H22: 50 | J22: √
B23: 4 | C23: I15 | D23: HDPE | E23: HDPE08 | F23: √ | G23: √ | H23: 45 | I23: √
B24: 4 | C24: J17 | D24: WATERGATE | E24: WG17 | F24: √ | G24: √ | H24: 40 | J24: √
B25: 4 | C25: J17 | D25: HDPE | E25: HDPE05 | F25: √ | G25: √ | H25: 60 | I25: √
B26: 4 | C26: I13 | D26: WATERGATE | E26: WG18 | F26: √ | G26: √ | H26: 50 | I26: √
B27: 4 | C27: I14 | D27: WATERGATE | E27: WG22 | F27: √ | G27: √ | H27: 45 | I27: √
B28: 4 | C28: G05 | D28: WATERGATE | E28: WG27 | F28: √ | G28: √ | H28: 50 | J28: √
B29: 4 | C29: E02 | D29: HDPE | E29: HDPE11 | F29: √ | G29: √ | H29: 60 | J29: √
B30: 4 | C30: E01 | D30: HDPE | E30: HDPE10 | F30: √ | G30: √ | H30: 55 | I30: √
B31: 4 | C31: E02 | D31: HDPE | E31: HDPE09 | F31: √ | G31: √ | H31: 60 | I31: √
B32: 4 | C32: F02 | D32: WATERGATE | E32: WG26 | F32: √ | G32: √ | H32: 40 | I32: √
B33: 4 | C33: I08 | D33: DRUM GATE | E33: DG16 | F33: √ | G33: √ | H33: 70 | I33: √
B34: 4 | C34: H8 | D34: DRUM GATE | E34: DG17 | F34: √ | G34: √ | H34: 75 | I34: √
B35: 4 | C35: H8 | D35: DRUM GATE | E35: DG18 | F35: √ | G35: √ | H35: 75 | I35: √
B36: 4 | C36: H17 | D36: HDPE | E36: HDPE06 | F36: √ | G36: √ | H36: 60 | I36: √
B37: 4 | C37: H16 | D37: HDPE | E37: HDPE07 | F37: √ | G37: √ | H37: 55 | I37: √
B38: 4 | C38: G09 | D38: WATERGATE | E38: WG28 | F38: √ | G38: √ | H38: 60 | I38: √

Sheet REKAPAN
B1: PT. SURYA INTISARI RAYA - 1
B2: KEBUN SEI LUKUT
B3: FR GROUP
A6: UPDATE | B6: S/D TGL 18 AGUSTUS 2026
A7: AFD | B7: BLOK | C7: TITIK KOORDINAT | D7: NOMOR PINTU AIR | E7: JEIS PINTU AIR | F7: KONDISI KETINGGIAN AIR (CM) | G7: KETERANGAN
A9: I | B9: A22 | C9: 0.629334,101.511331 | D9: WG01 | E9: WATERGATE | F9: 65 | G9: NORMAL | I9: DOKUMENTASI PENGECEKAN
B10: B22 | C10: 0.629104,101.520619 | D10: WG02 | E10: WATERGATE | F10: 75 | G10: NORMAL
B11: B21 | C11: 0.626629,101.525939 | D11: WG03 | E11: WATERGATE | F11: 70 | G11: NORMAL
B12: B21 | C12: 0.628887,101.523902 | D12: WG04 | E12: WATERGATE | F12: 70 | G12: NORMAL
B13: B20 | C13: 0.626360,101.526088 | D13: DG01 | E13: DRUMGATE | F13: 40 | G13: NORMAL
B14: C21 | C14: 0.626750,101.526514 | D14: WG05 | E14: WATERGATE | F14: 72 | G14: NORMAL
B15: C20 | C15: 0.624308,101.529971 | D15: WG06 | E15: WATERGATE | F15: 75 | G15: NORMAL
B16: C20 | C16: 0.624386,101.528289 | D16: DG02 | E16: DRUMGATE | F16: 55 | G16: NORMAL
B17: C17 | C17: 0.617466,101.533407 | D17: DG03 | E17: DRUMGATE | F17: 60 | G17: NORMAL
B18: C15 | C18: 0,612845,101.533407 | D18: DG04 | E18: DRUMGATE | F18: 60 | G18: NORMAL
B19: C14 | C19: 0.612559,101.533281 | D19: DG05 | E19: DRUMGATE | F19: 60 | G19: NORMAL
B20: C11 | C20: 0.603865,101.533889 | D20: WG07 | E20: WATERGATE | F20: 80 | G20: KEKERINGAN
B21: C10 | C21: 0.603510,101.533925 | D21: WG08 | E21: WATERGATE | F21: 70 | G21: KEKERINGAN
B22: D7 | C22: 0.594732,101.540468 | D22: WG09 | E22: WATERGATE | F22: +25 | G22: BANJIR
B23: D5 | C23: 0.590353,101.543947 | D23: WG10 | E23: WATERGATE | F23: 50 | G23: NORMAL
A24: TOTAL
A25: II | B25: D10 | C25: 0036.210;101032.077' | D25: WG11 | E25: WATERGATE | F25: 60 | G25: NORMAL
B26: F25 | C26: 0038.173;101033.405' | D26: WG12 | E26: WATERGATE | F26: 45 | G26: NORMAL
B27: F25 | C27: 0038.233;101033.652' | D27: DG06 | E27: DRUMGATE | F27: 70 | G27: NORMAL
A28: TOTAL
A29: III | B29: G19 | C29: ='TGL ROUDMAP PENGECEKAN'!D31 -> 0.622685, 101.567482 | D29: DG06 | E29: DRUMGATE | F29: 60 | G29: NORMAL
B30: G19 | C30: ='TGL ROUDMAP PENGECEKAN'!D32 -> 0.622820, 101.570032 | D30: HDPE01 | E30: HDPE | F30: 55 | G30: NORMAL
B31: H20 | C31: ='TGL ROUDMAP PENGECEKAN'!D33 -> 0.627122, 101.572180 | D31: DG07 | E31: DRUMGATE | F31: 45 | G31: NORMAL
B32: H21 | C32: ='TGL ROUDMAP PENGECEKAN'!D34 -> 0.627753, 101.572740 | D32: DG08 | E32: DRUMGATE | F32: 45 | G32: NORMAL
B33: H23 | C33: ='TGL ROUDMAP PENGECEKAN'!D35 -> 0.631985, 101.573525 | D33: DG09 | E33: DRUMGATE | F33: 55 | G33: NORMAL
B34: H23 | C34: ='TGL ROUDMAP PENGECEKAN'!D36 -> 0.631992, 101.573635 | D34: HDPE02 | E34: HDPE | F34: 65 | G34: NORMAL
B35: I20 | C35: ='TGL ROUDMAP PENGECEKAN'!D37 -> 0.625707, 101.588142 | D35: HDPE03 | E35: HDPE | F35: 60 | G35: NORMAL
B36: I22 | C36: ='TGL ROUDMAP PENGECEKAN'!D38 -> 0.631910, 101.584373 | D36: DG10 | E36: DRUMGATE | F36: 45 | G36: NORMAL
B37: I23 | C37: ='TGL ROUDMAP PENGECEKAN'!D39 -> 0.632093, 101.584567 | D37: DG11 | E37: DRUMGATE | F37: 40 | G37: NORMAL
B38: I23 | C38: ='TGL ROUDMAP PENGECEKAN'!D40 -> 0.632198, 101.584383 | D38: DG12 | E38: DRUMGATE | F38: 45 | G38: NORMAL
B39: I25 | C39: ='TGL ROUDMAP PENGECEKAN'!D41 -> 0.638847, 101.584553 | D39: DG13 | E39: DRUMGATE | F39: 40 | G39: NORMAL
B40: J18 | C40: ='TGL ROUDMAP PENGECEKAN'!D42 -> 0.620511, 101.592068 | D40: WG13 | E40: WATERGATE | F40: 50 | G40: NORMAL
B41: J18 | C41: ='TGL ROUDMAP PENGECEKAN'!D43 -> 0.622977, 101.589528 | D41: WG14 | E41: WATERGATE | F41: 35 | G41: NORMAL
... B44: J20 | C44: ='TGL ROUDMAP PENGECEKAN'!D46 -> 0.625690, 101.596447 | D44: HDPE04 | E44: HDPE | F44: 50 | G44: NORMAL
A45: TOTAL
...
